Workbook

Sheet Tabe of contents
A4: Table of contents
A7: Tab | B7: Content
A8: Prices S_ACS | B8: Sulfur, ACS prices and the freight cost from different region to Morocco
A9: Phosphate historical prices | B9: Annual phosphate prices
A10: Phosphate monthly prices | B10: Monthly phosphate prices
A11: Generated data | B11: Data used to generate forecasts
A12: Cockpit_monthly | B12: Monthly simulation result on forecasted data
A13: Cockpit_yearly | B13: Yearly simulation result on forecasted data
A14: Cockpit_Formula_7 | B14: Simulation result on forecasted data of formula 7
A15: Yearly_prices_forecast_CRU | B15: Yearly forecasted formula prices from CRU
A16: Yearly_prices_forecast_S&P | B16: Yearly forecasted formula prices from S&P
A17: Monthly_prices_forecast_direct | B17: Monthly forecasted prices for linked index formulas
A18: Monthly_prices_forcast_variat | B18: Monthly forecasted prices for index variation formulas
A19: Formula_7 | B19: Monthly forecasted prices for formula 7

Sheet Inputs >

Sheet Prices S_ACS
AB1: ConvCost=20+0,05×(SFOBME​+Fret)
J2: used for ACS production cost estimation
E3: Sulphuric Acid Bulk FOB | F3: Sulphuric Acid Bulk FOB | G3: Sulphuric Acid Bulk FOB | H3: Sulphuric Acid Bulk CFR | I3: Sulphur Bulk FOB | J3: Sulphur Bulk CFR | M3: Sulphuric Acid Bulk FOB | N3: Sulphuric Acid Bulk FOB | O3: Sulphuric Acid Bulk FOB | P3: Sulphur Bulk FOB | Q3: Sulphur Bulk CFR
E4: Japan/South Korea Spot | F4: NW Europe 30 days Spot | G4: China Spot | H4: North Africa, Spot | I4: Middle East Spot | J4: North Africa | M4: Japan/South Korea Spot | N4: NW Europe 30 days Spot | O4: China Spot | P4: Middle East Spot | Q4: North Africa | S4: Prix cibles Sulphuric Acid | AB4: Formule 1: Market Basket | AE4: Formule 2: Indice Composite basé sur Europe, chine et acid base ME
B5: Year | C5: Quarter | D5: Month | E5: ACS FOB Japan | F5: ACS FOB NW Europe | G5: ACS FOB China Spot | H5: ACS CFR North Africa Spot | I5: Sulphur Bulk FOB Middle East | J5: Sulphur Bulk CFR North Africa | M5: Fret Japan to Morocco | N5: Fret NW EU to Morocco | O5: Fret China to Morocco | P5: Fret Middle East to Morocco | Q5: Freight adjustment (CRU) | S5: ACS CFR North Africa | T5: IPP ACS Origine Europe | U5: IPP ACS origine Japon | V5: Ipp ACS Origine Chine | W5: Sulfur ME to CFR Morocco | X5: Sulfur North Africa to CFR Morocco | Y5: ACS S based from Sulfur ME | Z5: ACS S based from Sulfur North Africa | AB5: IPP_Acid = 40% × IPP_NWE + 30% × IPP_Japan + 30% × IPP_China | AC5: Gain par rapport à production sur place | AE5: IPP_Acid = min((70% × IPP_NWE + 30% × IPP_China); Acid S Based ME) | AF5: Gain par rapport à production sur place
B6: 2002 | C6: 2 | D6: 5 | F6: 6 | J6: 33 | M6: 53.686275 | N6: 23.388235 | O6: =IFERROR(M6*0.9, "") -> 48.317647 | P6: 29.165429 | Q6: 20 | S6: =T6*S7/T7 -> 78.098657 | T6: =IF(F6=0, "", F6+N6) -> 29.388235 | U6: =IFERROR( E6+M6, "") | V6: =IFERROR( G6+O6, "") | W6: =IFERROR(I6+P6, "") | X6: =J6+Q6 -> 53 | Y6: =IFERROR((I6+P6)*0.33+18, "") | Z6: =IF(J6=0,0,(J6+Q6)*0.33+18) -> 35.49 | AB6: =IF(OR(T6="", U6="", V6=""), "", MAX(S6,T6)*40%+U6*30%+V6*30%) | AC6: =IF(AB6="", "", MAX(Y6, Z6)-AB6) | AE6: =IFERROR(MIN((MAX(S6,T6)*70%+V6*30%), Z6), "") | AF6: =IF(AE6="", "", MAX(AB6, AC6)-AE6)
B7: 2002 | C7: 2 | D7: 6 | F7: 6 | J7: 33 | M7: 53.686275 | N7: 23.388235 | O7: =IFERROR(M7*0.9, "") -> 48.317647 | P7: 29.165429 | Q7: 20 | S7: =T7*S8/T8 -> 78.098657 | T7: =IF(F7=0, "", F7+N7) -> 29.388235 | U7: =IFERROR( E7+M7, "") | V7: =IFERROR( G7+O7, "") | W7: =IFERROR(I7+P7, "") | X7: =J7+Q7 -> 53 | Y7: =IFERROR((I7+P7)*0.33+18, "") | Z7: =IF(J7=0,0,(J7+Q7)*0.33+18) -> 35.49 | AB7: =IF(OR(T7="", U7="", V7=""), "", MAX(S7,T7)*40%+U7*30%+V7*30%) | AC7: =IF(AB7="", "", MAX(Y7, Z7)-AB7) | AE7: =IFERROR(MIN((MAX(S7,T7)*70%+V7*30%), Z7), "") | AF7: =IF(AE7="", "", MAX(AB7, AC7)-AE7)
B8: 2002 | C8: 3 | D8: 7 | F8: 8 | J8: 39 | M8: 53.686275 | N8: 23.388235 | O8: =IFERROR(M8*0.9, "") -> 48.317647 | P8: 29.165429 | Q8: 20 | S8: =T8*S9/T9 -> 83.413617 | T8: =IF(F8=0, "", F8+N8) -> 31.388235 | U8: =IFERROR( E8+M8, "") | V8: =IFERROR( G8+O8, "") | W8: =IFERROR(I8+P8, "") | X8: =J8+Q8 -> 59 | Y8: =IFERROR((I8+P8)*0.33+18, "") | Z8: =IF(J8=0,0,(J8+Q8)*0.33+18) -> 37.47 | AB8: =IF(OR(T8="", U8="", V8=""), "", MAX(S8,T8)*40%+U8*30%+V8*30%) | AC8: =IF(AB8="", "", MAX(Y8, Z8)-AB8) | AE8: =IFERROR(MIN((MAX(S8,T8)*70%+V8*30%), Z8), "") | AF8: =IF(AE8="", "", MAX(AB8, AC8)-AE8)
B9: 2002 | C9: 3 | D9: 8 | F9: 8 | J9: 38.5 | M9: 53.686275 | N9: 23.388235 | O9: =IFERROR(M9*0.9, "") -> 48.317647 | P9: 29.165429 | Q9: 20 | S9: =T9*S10/T10 -> 83.413617 | T9: =IF(F9=0, "", F9+N9) -> 31.388235 | U9: =IFERROR( E9+M9, "") | V9: =IFERROR( G9+O9, "") | W9: =IFERROR(I9+P9, "") | X9: =J9+Q9 -> 58.5 | Y9: =IFERROR((I9+P9)*0.33+18, "") | Z9: =IF(J9=0,0,(J9+Q9)*0.33+18) -> 37.305 | AB9: =IF(OR(T9="", U9="", V9=""), "", MAX(S9,T9)*40%+U9*30%+V9*30%) | AC9: =IF(AB9="", "", MAX(Y9, Z9)-AB9) | AE9: =IFERROR(MIN((MAX(S9,T9)*70%+V9*30%), Z9), "") | AF9: =IF(AE9="", "", MAX(AB9, AC9)-AE9)
B10: 2002 | C10: 3 | D10: 9 | F10: 8 | J10: 38 | M10: 53.686275 | N10: 23.388235 | O10: =IFERROR(M10*0.9, "") -> 48.317647 | P10: 29.165429 | Q10: 20 | S10: =T10*S11/T11 -> 83.413617 | T10: =IF(F10=0, "", F10+N10) -> 31.388235 | U10: =IFERROR( E10+M10, "") | V10: =IFERROR( G10+O10, "") | W10: =IFERROR(I10+P10, "") | X10: =J10+Q10 -> 58 | Y10: =IFERROR((I10+P10)*0.33+18, "") | Z10: =IF(J10=0,0,(J10+Q10)*0.33+18) -> 37.14 | AB10: =IF(OR(T10="", U10="", V10=""), "", MAX(S10,T10)*40%+U10*30%+V10*30%) | AC10: =IF(AB10="", "", MAX(Y10, Z10)-AB10) | AE10: =IFERROR(MIN((MAX(S10,T10)*70%+V10*30%), Z10), "") | AF10: =IF(AE10="", "", MAX(AB10, AC10)-AE10)
B11: 2002 | C11: 4 | D11: 10 | F11: 8 | J11: 38 | M11: 53.686275 | N11: 23.388235 | O11: =IFERROR(M11*0.9, "") -> 48.317647 | P11: 29.165429 | Q11: 20 | S11: =T11*S12/T12 -> 83.413617 | T11: =IF(F11=0, "", F11+N11) -> 31.388235 | U11: =IFERROR( E11+M11, "") | V11: =IFERROR( G11+O11, "") | W11: =IFERROR(I11+P11, "") | X11: =J11+Q11 -> 58 | Y11: =IFERROR((I11+P11)*0.33+18, "") | Z11: =IF(J11=0,0,(J11+Q11)*0.33+18) -> 37.14 | AB11: =IF(OR(T11="", U11="", V11=""), "", MAX(S11,T11)*40%+U11*30%+V11*30%) | AC11: =IF(AB11="", "", MAX(Y11, Z11)-AB11) | AE11: =IFERROR(MIN((MAX(S11,T11)*70%+V11*30%), Z11), "") | AF11: =IF(AE11="", "", MAX(AB11, AC11)-AE11)
B12: 2002 | C12: 4 | D12: 11 | F12: 11 | J12: 39 | M12: 53.686275 | N12: 23.388235 | O12: =IFERROR(M12*0.9, "") -> 48.317647 | P12: 29.165429 | Q12: 20 | S12: =T12*S13/T13 -> 91.386058 | T12: =IF(F12=0, "", F12+N12) -> 34.388235 | U12: =IFERROR( E12+M12, "") | V12: =IFERROR( G12+O12, "") | W12: =IFERROR(I12+P12, "") | X12: =J12+Q12 -> 59 | Y12: =IFERROR((I12+P12)*0.33+18, "") | Z12: =IF(J12=0,0,(J12+Q12)*0.33+18) -> 37.47 | AB12: =IF(OR(T12="", U12="", V12=""), "", MAX(S12,T12)*40%+U12*30%+V12*30%) | AC12: =IF(AB12="", "", MAX(Y12, Z12)-AB12) | AE12: =IFERROR(MIN((MAX(S12,T12)*70%+V12*30%), Z12), "") | AF12: =IF(AE12="", "", MAX(AB12, AC12)-AE12)
B13: 2002 | C13: 4 | D13: 12 | F13: 11 | J13: 39 | M13: 53.686275 | N13: 23.388235 | O13: =IFERROR(M13*0.9, "") -> 48.317647 | P13: 29.165429 | Q13: 20 | S13: =T13*S14/T14 -> 91.386058 | T13: =IF(F13=0, "", F13+N13) -> 34.388235 | U13: =IFERROR( E13+M13, "") | V13: =IFERROR( G13+O13, "") | W13: =IFERROR(I13+P13, "") | X13: =J13+Q13 -> 59 | Y13: =IFERROR((I13+P13)*0.33+18, "") | Z13: =IF(J13=0,0,(J13+Q13)*0.33+18) -> 37.47 | AB13: =IF(OR(T13="", U13="", V13=""), "", MAX(S13,T13)*40%+U13*30%+V13*30%) | AC13: =IF(AB13="", "", MAX(Y13, Z13)-AB13) | AE13: =IFERROR(MIN((MAX(S13,T13)*70%+V13*30%), Z13), "") | AF13: =IF(AE13="", "", MAX(AB13, AC13)-AE13)
B14: 2003 | C14: 1 | D14: 1 | F14: 11.666667 | J14: 57.333333 | M14: 53.686275 | N14: 23.388235 | O14: =IFERROR(M14*0.9, "") -> 48.317647 | P14: 29.165429 | Q14: 20 | S14: =T14*S15/T15 -> 93.157712 | T14: =IF(F14=0, "", F14+N14) -> 35.054902 | U14: =IFERROR( E14+M14, "") | V14: =IFERROR( G14+O14, "") | W14: =IFERROR(I14+P14, "") | X14: =J14+Q14 -> 77.333333 | Y14: =IFERROR((I14+P14)*0.33+18, "") | Z14: =IF(J14=0,0,(J14+Q14)*0.33+18) -> 43.52 | AB14: =IF(OR(T14="", U14="", V14=""), "", MAX(S14,T14)*40%+U14*30%+V14*30%) | AC14: =IF(AB14="", "", MAX(Y14, Z14)-AB14) | AE14: =IFERROR(MIN((MAX(S14,T14)*70%+V14*30%), Z14), "") | AF14: =IF(AE14="", "", MAX(AB14, AC14)-AE14)
B15: 2003 | C15: 1 | D15: 2 | F15: 13 | J15: 61 | M15: 53.686275 | N15: 23.388235 | O15: =IFERROR(M15*0.9, "") -> 48.317647 | P15: 29.165429 | Q15: 20 | S15: =T15*S16/T16 -> 96.701019 | T15: =IF(F15=0, "", F15+N15) -> 36.388235 | U15: =IFERROR( E15+M15, "") | V15: =IFERROR( G15+O15, "") | W15: =IFERROR(I15+P15, "") | X15: =J15+Q15 -> 81 | Y15: =IFERROR((I15+P15)*0.33+18, "") | Z15: =IF(J15=0,0,(J15+Q15)*0.33+18) -> 44.73 | AB15: =IF(OR(T15="", U15="", V15=""), "", MAX(S15,T15)*40%+U15*30%+V15*30%) | AC15: =IF(AB15="", "", MAX(Y15, Z15)-AB15) | AE15: =IFERROR(MIN((MAX(S15,T15)*70%+V15*30%), Z15), "") | AF15: =IF(AE15="", "", MAX(AB15, AC15)-AE15)
B16: 2003 | C16: 1 | D16: 3 | F16: 13 | J16: 62 | M16: 53.686275 | N16: 23.388235 | O16: =IFERROR(M16*0.9, "") -> 48.317647 | P16: 29.165429 | Q16: 20 | S16: =T16*S17/T17 -> 96.701019 | T16: =IF(F16=0, "", F16+N16) -> 36.388235 | U16: =IFERROR( E16+M16, "") | V16: =IFERROR( G16+O16, "") | W16: =IFERROR(I16+P16, "") | X16: =J16+Q16 -> 82 | Y16: =IFERROR((I16+P16)*0.33+18, "") | Z16: =IF(J16=0,0,(J16+Q16)*0.33+18) -> 45.06 | AB16: =IF(OR(T16="", U16="", V16=""), "", MAX(S16,T16)*40%+U16*30%+V16*30%) | AC16: =IF(AB16="", "", MAX(Y16, Z16)-AB16) | AE16: =IFERROR(MIN((MAX(S16,T16)*70%+V16*30%), Z16), "") | AF16: =IF(AE16="", "", MAX(AB16, AC16)-AE16)
B17: 2003 | C17: 2 | D17: 4 | F17: 13 | J17: 60.5 | M17: 53.686275 | N17: 23.388235 | O17: =IFERROR(M17*0.9, "") -> 48.317647 | P17: 29.165429 | Q17: 20 | S17: =T17*S18/T18 -> 96.701019 | T17: =IF(F17=0, "", F17+N17) -> 36.388235 | U17: =IFERROR( E17+M17, "") | V17: =IFERROR( G17+O17, "") | W17: =IFERROR(I17+P17, "") | X17: =J17+Q17 -> 80.5 | Y17: =IFERROR((I17+P17)*0.33+18, "") | Z17: =IF(J17=0,0,(J17+Q17)*0.33+18) -> 44.565 | AB17: =IF(OR(T17="", U17="", V17=""), "", MAX(S17,T17)*40%+U17*30%+V17*30%) | AC17: =IF(AB17="", "", MAX(Y17, Z17)-AB17) | AE17: =IFERROR(MIN((MAX(S17,T17)*70%+V17*30%), Z17), "") | AF17: =IF(AE17="", "", MAX(AB17, AC17)-AE17)
B18: 2003 | C18: 2 | D18: 5 | F18: 13 | J18: 60.5 | M18: 53.686275 | N18: 23.388235 | O18: =IFERROR(M18*0.9, "") -> 48.317647 | P18: 29.165429 | Q18: 20 | S18: =T18*S19/T19 -> 96.701019 | T18: =IF(F18=0, "", F18+N18) -> 36.388235 | U18: =IFERROR( E18+M18, "") | V18: =IFERROR( G18+O18, "") | W18: =IFERROR(I18+P18, "") | X18: =J18+Q18 -> 80.5 | Y18: =IFERROR((I18+P18)*0.33+18, "") | Z18: =IF(J18=0,0,(J18+Q18)*0.33+18) -> 44.565 | AB18: =IF(OR(T18="", U18="", V18=""), "", MAX(S18,T18)*40%+U18*30%+V18*30%) | AC18: =IF(AB18="", "", MAX(Y18, Z18)-AB18) | AE18: =IFERROR(MIN((MAX(S18,T18)*70%+V18*30%), Z18), "") | AF18: =IF(AE18="", "", MAX(AB18, AC18)-AE18)
B19: 2003 | C19: 2 | D19: 6 | F19: 17.5 | I19: 63 | J19: 60.5 | M19: 53.686275 | N19: 23.388235 | O19: =IFERROR(M19*0.9, "") -> 48.317647 | P19: 29.165429 | Q19: 20 | S19: =T19*S20/T20 -> 108.65968 | T19: =IF(F19=0, "", F19+N19) -> 40.888235 | U19: =IFERROR( E19+M19, "") | V19: =IFERROR( G19+O19, "") | W19: =IFERROR(I19+P19, "") -> 92.165429 | X19: =J19+Q19 -> 80.5 | Y19: =IFERROR((I19+P19)*0.33+18, "") -> 48.414592 | Z19: =IF(J19=0,0,(J19+Q19)*0.33+18) -> 44.565 | AB19: =IF(OR(T19="", U19="", V19=""), "", MAX(S19,T19)*40%+U19*30%+V19*30%) | AC19: =IF(AB19="", "", MAX(Y19, Z19)-AB19) | AE19: =IFERROR(MIN((MAX(S19,T19)*70%+V19*30%), Z19), "") | AF19: =IF(AE19="", "", MAX(AB19, AC19)-AE19)
B20: 2003 | C20: 3 | D20: 7 | F20: 22 | I20: 59 | J20: 65.333333 | M20: 53.686275 | N20: 23.388235 | O20: =IFERROR(M20*0.9, "") -> 48.317647 | P20: 29.165429 | Q20: 20 | S20: =T20*S21/T21 -> 120.61834 | T20: =IF(F20=0, "", F20+N20) -> 45.388235 | U20: =IFERROR( E20+M20, "") | V20: =IFERROR( G20+O20, "") | W20: =IFERROR(I20+P20, "") -> 88.165429 | X20: =J20+Q20 -> 85.333333 | Y20: =IFERROR((I20+P20)*0.33+18, "") -> 47.094592 | Z20: =IF(J20=0,0,(J20+Q20)*0.33+18) -> 46.16 | AB20: =IF(OR(T20="", U20="", V20=""), "", MAX(S20,T20)*40%+U20*30%+V20*30%) | AC20: =IF(AB20="", "", MAX(Y20, Z20)-AB20) | AE20: =IFERROR(MIN((MAX(S20,T20)*70%+V20*30%), Z20), "") | AF20: =IF(AE20="", "", MAX(AB20, AC20)-AE20)
B21: 2003 | C21: 3 | D21: 8 | F21: 22 | I21: 58 | J21: 69.5 | M21: 53.686275 | N21: 23.388235 | O21: =IFERROR(M21*0.9, "") -> 48.317647 | P21: 29.165429 | Q21: 20 | S21: =T21*S22/T22 -> 120.61834 | T21: =IF(F21=0, "", F21+N21) -> 45.388235 | U21: =IFERROR( E21+M21, "") | V21: =IFERROR( G21+O21, "") | W21: =IFERROR(I21+P21, "") -> 87.165429 | X21: =J21+Q21 -> 89.5 | Y21: =IFERROR((I21+P21)*0.33+18, "") -> 46.764592 | Z21: =IF(J21=0,0,(J21+Q21)*0.33+18) -> 47.535 | AB21: =IF(OR(T21="", U21="", V21=""), "", MAX(S21,T21)*40%+U21*30%+V21*30%) | AC21: =IF(AB21="", "", MAX(Y21, Z21)-AB21) | AE21: =IFERROR(MIN((MAX(S21,T21)*70%+V21*30%), Z21), "") | AF21: =IF(AE21="", "", MAX(AB21, AC21)-AE21)
B22: 2003 | C22: 3 | D22: 9 | F22: 22 | I22: 61.5 | J22: 69.5 | M22: 53.686275 | N22: 23.388235 | O22: =IFERROR(M22*0.9, "") -> 48.317647 | P22: 29.165429 | Q22: 20 | S22: =T22*S23/T23 -> 120.61834 | T22: =IF(F22=0, "", F22+N22) -> 45.388235 | U22: =IFERROR( E22+M22, "") | V22: =IFERROR( G22+O22, "") | W22: =IFERROR(I22+P22, "") -> 90.665429 | X22: =J22+Q22 -> 89.5 | Y22: =IFERROR((I22+P22)*0.33+18, "") -> 47.919592 | Z22: =IF(J22=0,0,(J22+Q22)*0.33+18) -> 47.535 | AB22: =IF(OR(T22="", U22="", V22=""), "", MAX(S22,T22)*40%+U22*30%+V22*30%) | AC22: =IF(AB22="", "", MAX(Y22, Z22)-AB22) | AE22: =IFERROR(MIN((MAX(S22,T22)*70%+V22*30%), Z22), "") | AF22: =IF(AE22="", "", MAX(AB22, AC22)-AE22)
B23: 2003 | C23: 4 | D23: 10 | F23: 28 | I23: 63 | J23: 69.75 | M23: 53.686275 | N23: 23.388235 | O23: =IFERROR(M23*0.9, "") -> 48.317647 | P23: 29.165429 | Q23: 20 | S23: =T23*S24/T24 -> 136.56322 | T23: =IF(F23=0, "", F23+N23) -> 51.388235 | U23: =IFERROR( E23+M23, "") | V23: =IFERROR( G23+O23, "") | W23: =IFERROR(I23+P23, "") -> 92.165429 | X23: =J23+Q23 -> 89.75 | Y23: =IFERROR((I23+P23)*0.33+18, "") -> 48.414592 | Z23: =IF(J23=0,0,(J23+Q23)*0.33+18) -> 47.6175 | AB23: =IF(OR(T23="", U23="", V23=""), "", MAX(S23,T23)*40%+U23*30%+V23*30%) | AC23: =IF(AB23="", "", MAX(Y23, Z23)-AB23) | AE23: =IFERROR(MIN((MAX(S23,T23)*70%+V23*30%), Z23), "") | AF23: =IF(AE23="", "", MAX(AB23, AC23)-AE23)
B24: 2003 | C24: 4 | D24: 11 | F24: 28 | I24: 68 | J24: 71 | M24: 53.686275 | N24: 23.388235 | O24: =IFERROR(M24*0.9, "") -> 48.317647 | P24: 29.165429 | Q24: 20 | S24: =T24*S25/T25 -> 136.56322 | T24: =IF(F24=0, "", F24+N24) -> 51.388235 | U24: =IFERROR( E24+M24, "") | V24: =IFERROR( G24+O24, "") | W24: =IFERROR(I24+P24, "") -> 97.165429 | X24: =J24+Q24 -> 91 | Y24: =IFERROR((I24+P24)*0.33+18, "") -> 50.064592 | Z24: =IF(J24=0,0,(J24+Q24)*0.33+18) -> 48.03 | AB24: =IF(OR(T24="", U24="", V24=""), "", MAX(S24,T24)*40%+U24*30%+V24*30%) | AC24: =IF(AB24="", "", MAX(Y24, Z24)-AB24) | AE24: =IFERROR(MIN((MAX(S24,T24)*70%+V24*30%), Z24), "") | AF24: =IF(AE24="", "", MAX(AB24, AC24)-AE24)
B25: 2003 | C25: 4 | D25: 12 | F25: 28 | I25: 72 | J25: 71 | M25: 53.686275 | N25: 23.388235 | O25: =IFERROR(M25*0.9, "") -> 48.317647 | P25: 29.165429 | Q25: 20 | S25: =T25*S26/T26 -> 136.56322 | T25: =IF(F25=0, "", F25+N25) -> 51.388235 | U25: =IFERROR( E25+M25, "") | V25: =IFERROR( G25+O25, "") | W25: =IFERROR(I25+P25, "") -> 101.16543 | X25: =J25+Q25 -> 91 | Y25: =IFERROR((I25+P25)*0.33+18, "") -> 51.384592 | Z25: =IF(J25=0,0,(J25+Q25)*0.33+18) -> 48.03 | AB25: =IF(OR(T25="", U25="", V25=""), "", MAX(S25,T25)*40%+U25*30%+V25*30%) | AC25: =IF(AB25="", "", MAX(Y25, Z25)-AB25) | AE25: =IFERROR(MIN((MAX(S25,T25)*70%+V25*30%), Z25), "") | AF25: =IF(AE25="", "", MAX(AB25, AC25)-AE25)
B26: 2004 | C26: 1 | D26: 1 | F26: 31.5 | I26: 74 | J26: 76 | M26: 53.686275 | N26: 23.388235 | O26: =IFERROR(M26*0.9, "") -> 48.317647 | P26: 29.165429 | Q26: 20 | S26: =T26*S27/T27 -> 145.8644 | T26: =IF(F26=0, "", F26+N26) -> 54.888235 | U26: =IFERROR( E26+M26, "") | V26: =IFERROR( G26+O26, "") | W26: =IFERROR(I26+P26, "") -> 103.16543 | X26: =J26+Q26 -> 96 | Y26: =IFERROR((I26+P26)*0.33+18, "") -> 52.044592 | Z26: =IF(J26=0,0,(J26+Q26)*0.33+18) -> 49.68 | AB26: =IF(OR(T26="", U26="", V26=""), "", MAX(S26,T26)*40%+U26*30%+V26*30%) | AC26: =IF(AB26="", "", MAX(Y26, Z26)-AB26) | AE26: =IFERROR(MIN((MAX(S26,T26)*70%+V26*30%), Z26), "") | AF26: =IF(AE26="", "", MAX(AB26, AC26)-AE26)
B27: 2004 | C27: 1 | D27: 2 | F27: 35 | I27: 66 | J27: 78 | M27: 53.686275 | N27: 23.388235 | O27: =IFERROR(M27*0.9, "") -> 48.317647 | P27: 29.165429 | Q27: 20 | S27: =T27*S28/T28 -> 155.16559 | T27: =IF(F27=0, "", F27+N27) -> 58.388235 | U27: =IFERROR( E27+M27, "") | V27: =IFERROR( G27+O27, "") | W27: =IFERROR(I27+P27, "") -> 95.165429 | X27: =J27+Q27 -> 98 | Y27: =IFERROR((I27+P27)*0.33+18, "") -> 49.404592 | Z27: =IF(J27=0,0,(J27+Q27)*0.33+18) -> 50.34 | AB27: =IF(OR(T27="", U27="", V27=""), "", MAX(S27,T27)*40%+U27*30%+V27*30%) | AC27: =IF(AB27="", "", MAX(Y27, Z27)-AB27) | AE27: =IFERROR(MIN((MAX(S27,T27)*70%+V27*30%), Z27), "") | AF27: =IF(AE27="", "", MAX(AB27, AC27)-AE27)
B28: 2004 | C28: 1 | D28: 3 | F28: 35 | I28: 64.333333 | J28: 77.5 | M28: 53.686275 | N28: 23.388235 | O28: =IFERROR(M28*0.9, "") -> 48.317647 | P28: 29.165429 | Q28: 20 | S28: =T28*S29/T29 -> 155.16559 | T28: =IF(F28=0, "", F28+N28) -> 58.388235 | U28: =IFERROR( E28+M28, "") | V28: =IFERROR( G28+O28, "") | W28: =IFERROR(I28+P28, "") -> 93.498763 | X28: =J28+Q28 -> 97.5 | Y28: =IFERROR((I28+P28)*0.33+18, "") -> 48.854592 | Z28: =IF(J28=0,0,(J28+Q28)*0.33+18) -> 50.175 | AB28: =IF(OR(T28="", U28="", V28=""), "", MAX(S28,T28)*40%+U28*30%+V28*30%) | AC28: =IF(AB28="", "", MAX(Y28, Z28)-AB28) | AE28: =IFERROR(MIN((MAX(S28,T28)*70%+V28*30%), Z28), "") | AF28: =IF(AE28="", "", MAX(AB28, AC28)-AE28)
B29: 2004 | C29: 2 | D29: 4 | F29: 35 | I29: 61.333333 | J29: 77.333333 | M29: 53.686275 | N29: 23.388235 | O29: =IFERROR(M29*0.9, "") -> 48.317647 | P29: 29.165429 | Q29: 20 | S29: =T29*S30/T30 -> 155.16559 | T29: =IF(F29=0, "", F29+N29) -> 58.388235 | U29: =IFERROR( E29+M29, "") | V29: =IFERROR( G29+O29, "") | W29: =IFERROR(I29+P29, "") -> 90.498763 | X29: =J29+Q29 -> 97.333333 | Y29: =IFERROR((I29+P29)*0.33+18, "") -> 47.864592 | Z29: =IF(J29=0,0,(J29+Q29)*0.33+18) -> 50.12 | AB29: =IF(OR(T29="", U29="", V29=""), "", MAX(S29,T29)*40%+U29*30%+V29*30%) | AC29: =IF(AB29="", "", MAX(Y29, Z29)-AB29) | AE29: =IFERROR(MIN((MAX(S29,T29)*70%+V29*30%), Z29), "") | AF29: =IF(AE29="", "", MAX(AB29, AC29)-AE29)
B30: 2004 | C30: 2 | D30: 5 | F30: 35 | I30: 65 | J30: 78 | M30: 53.686275 | N30: 23.388235 | O30: =IFERROR(M30*0.9, "") -> 48.317647 | P30: 29.165429 | Q30: 20 | S30: =T30*S31/T31 -> 155.16559 | T30: =IF(F30=0, "", F30+N30) -> 58.388235 | U30: =IFERROR( E30+M30, "") | V30: =IFERROR( G30+O30, "") | W30: =IFERROR(I30+P30, "") -> 94.165429 | X30: =J30+Q30 -> 98 | Y30: =IFERROR((I30+P30)*0.33+18, "") -> 49.074592 | Z30: =IF(J30=0,0,(J30+Q30)*0.33+18) -> 50.34 | AB30: =IF(OR(T30="", U30="", V30=""), "", MAX(S30,T30)*40%+U30*30%+V30*30%) | AC30: =IF(AB30="", "", MAX(Y30, Z30)-AB30) | AE30: =IFERROR(MIN((MAX(S30,T30)*70%+V30*30%), Z30), "") | AF30: =IF(AE30="", "", MAX(AB30, AC30)-AE30)
... B93: 2009 | C93: 3 | D93: 8 | F93: -5 | I93: 34.75 | J93: 37.5 | M93: 53.686275 | N93: 23.388235 | O93: =IFERROR(M93*0.9, "") -> 48.317647 | P93: 24.5 | Q93: 20 | S93: =T93*S94/T94 -> 48.866373 | T93: =IF(F93=0, "", F93+N93) -> 18.388235 | U93: =IFERROR( E93+M93, "") | V93: =IFERROR( G93+O93, "") | W93: =IFERROR(I93+P93, "") -> 59.25 | X93: =J93+Q93 -> 57.5 | Y93: =IFERROR((I93+P93)*0.33+18, "") -> 37.5525 | Z93: =IF(J93=0,0,(J93+Q93)*0.33+18) -> 36.975 | AB93: =IF(OR(T93="", U93="", V93=""), "", MAX(S93,T93)*40%+U93*30%+V93*30%) | AC93: =IF(AB93="", "", MAX(Y93, Z93)-AB93) | AE93: =IFERROR(MIN((MAX(S93,T93)*70%+V93*30%), Z93), "") | AF93: =IF(AE93="", "", MAX(AB93, AC93)-AE93)
B94: 2009 | C94: 3 | D94: 9 | F94: 0 | I94: 40 | J94: 37.5 | M94: 53.686275 | N94: 23.388235 | O94: =IFERROR(M94*0.9, "") -> 48.317647 | P94: 22.75 | Q94: 20 | S94: =T94*S95/T95 -> 48.866373 | T94: =T93 -> 18.388235 | U94: =IFERROR( E94+M94, "") | V94: =IFERROR( G94+O94, "") | W94: =IFERROR(I94+P94, "") -> 62.75 | X94: =J94+Q94 -> 57.5 | Y94: =IFERROR((I94+P94)*0.33+18, "") -> 38.7075 | Z94: =IF(J94=0,0,(J94+Q94)*0.33+18) -> 36.975 | AB94: =IF(OR(T94="", U94="", V94=""), "", MAX(S94,T94)*40%+U94*30%+V94*30%) | AC94: =IF(AB94="", "", MAX(Y94, Z94)-AB94) | AE94: =IFERROR(MIN((MAX(S94,T94)*70%+V94*30%), Z94), "") | AF94: =IF(AE94="", "", MAX(AB94, AC94)-AE94)
B95: 2009 | C95: 4 | D95: 10 | F95: -5.2 | I95: 44.6 | J95: 37.5 | M95: 53.686275 | N95: 23.388235 | O95: =IFERROR(M95*0.9, "") -> 48.317647 | P95: 22.6 | Q95: 20 | S95: =T95*S96/T96 -> 48.334877 | T95: =IF(F95=0, "", F95+N95) -> 18.188235 | U95: =IFERROR( E95+M95, "") | V95: =IFERROR( G95+O95, "") | W95: =IFERROR(I95+P95, "") -> 67.2 | X95: =J95+Q95 -> 57.5 | Y95: =IFERROR((I95+P95)*0.33+18, "") -> 40.176 | Z95: =IF(J95=0,0,(J95+Q95)*0.33+18) -> 36.975 | AB95: =IF(OR(T95="", U95="", V95=""), "", MAX(S95,T95)*40%+U95*30%+V95*30%) | AC95: =IF(AB95="", "", MAX(Y95, Z95)-AB95) | AE95: =IFERROR(MIN((MAX(S95,T95)*70%+V95*30%), Z95), "") | AF95: =IF(AE95="", "", MAX(AB95, AC95)-AE95)
B96: 2009 | C96: 4 | D96: 11 | F96: -13 | I96: 55.75 | J96: 37.5 | M96: 53.686275 | N96: 23.388235 | O96: =IFERROR(M96*0.9, "") -> 48.317647 | P96: 25.25 | Q96: 20 | S96: =T96*S97/T97 -> 27.606531 | T96: =IF(F96=0, "", F96+N96) -> 10.388235 | U96: =IFERROR( E96+M96, "") | V96: =IFERROR( G96+O96, "") | W96: =IFERROR(I96+P96, "") -> 81 | X96: =J96+Q96 -> 57.5 | Y96: =IFERROR((I96+P96)*0.33+18, "") -> 44.73 | Z96: =IF(J96=0,0,(J96+Q96)*0.33+18) -> 36.975 | AB96: =IF(OR(T96="", U96="", V96=""), "", MAX(S96,T96)*40%+U96*30%+V96*30%) | AC96: =IF(AB96="", "", MAX(Y96, Z96)-AB96) | AE96: =IFERROR(MIN((MAX(S96,T96)*70%+V96*30%), Z96), "") | AF96: =IF(AE96="", "", MAX(AB96, AC96)-AE96)
B97: 2009 | C97: 4 | D97: 12 | F97: -0.6 | I97: 68.2 | J97: 37.5 | M97: 53.686275 | N97: 23.388235 | O97: =IFERROR(M97*0.9, "") -> 48.317647 | P97: 28.5 | Q97: 20 | S97: =T97*S98/T98 -> 60.559287 | T97: =IF(F97=0, "", F97+N97) -> 22.788235 | U97: =IFERROR( E97+M97, "") | V97: =IFERROR( G97+O97, "") | W97: =IFERROR(I97+P97, "") -> 96.7 | X97: =J97+Q97 -> 57.5 | Y97: =IFERROR((I97+P97)*0.33+18, "") -> 49.911 | Z97: =IF(J97=0,0,(J97+Q97)*0.33+18) -> 36.975 | AB97: =IF(OR(T97="", U97="", V97=""), "", MAX(S97,T97)*40%+U97*30%+V97*30%) | AC97: =IF(AB97="", "", MAX(Y97, Z97)-AB97) | AE97: =IFERROR(MIN((MAX(S97,T97)*70%+V97*30%), Z97), "") | AF97: =IF(AE97="", "", MAX(AB97, AC97)-AE97)
B98: 2010 | C98: 1 | D98: 1 | F98: 20 | I98: 122.75 | J98: 63.875 | M98: 53.686275 | N98: 23.388235 | O98: =IFERROR(M98*0.9, "") -> 48.317647 | P98: 30.25 | Q98: 20 | S98: =T98*S99/T99 -> 115.30338 | T98: =IF(F98=0, "", F98+N98) -> 43.388235 | U98: =IFERROR( E98+M98, "") | V98: =IFERROR( G98+O98, "") | W98: =IFERROR(I98+P98, "") -> 153 | X98: =J98+Q98 -> 83.875 | Y98: =IFERROR((I98+P98)*0.33+18, "") -> 68.49 | Z98: =IF(J98=0,0,(J98+Q98)*0.33+18) -> 45.67875 | AB98: =IF(OR(T98="", U98="", V98=""), "", MAX(S98,T98)*40%+U98*30%+V98*30%) | AC98: =IF(AB98="", "", MAX(Y98, Z98)-AB98) | AE98: =IFERROR(MIN((MAX(S98,T98)*70%+V98*30%), Z98), "") | AF98: =IF(AE98="", "", MAX(AB98, AC98)-AE98)
B99: 2010 | C99: 1 | D99: 2 | F99: 47.5 | I99: 167 | J99: 67.625 | M99: 53.686275 | N99: 23.388235 | O99: =IFERROR(M99*0.9, "") -> 48.317647 | P99: 28.25 | Q99: 20 | S99: =T99*S100/T100 -> 188.38409 | T99: =IF(F99=0, "", F99+N99) -> 70.888235 | U99: =IFERROR( E99+M99, "") | V99: =IFERROR( G99+O99, "") | W99: =IFERROR(I99+P99, "") -> 195.25 | X99: =J99+Q99 -> 87.625 | Y99: =IFERROR((I99+P99)*0.33+18, "") -> 82.4325 | Z99: =IF(J99=0,0,(J99+Q99)*0.33+18) -> 46.91625 | AB99: =IF(OR(T99="", U99="", V99=""), "", MAX(S99,T99)*40%+U99*30%+V99*30%) | AC99: =IF(AB99="", "", MAX(Y99, Z99)-AB99) | AE99: =IFERROR(MIN((MAX(S99,T99)*70%+V99*30%), Z99), "") | AF99: =IF(AE99="", "", MAX(AB99, AC99)-AE99)
B100: 2010 | C100: 1 | D100: 3 | F100: 50 | I100: 181 | J100: 67 | M100: 53.686275 | N100: 23.388235 | O100: =IFERROR(M100*0.9, "") -> 48.317647 | P100: 33.25 | Q100: 20 | S100: =T100*S101/T101 -> 195.02779 | T100: =IF(F100=0, "", F100+N100) -> 73.388235 | U100: =IFERROR( E100+M100, "") | V100: =IFERROR( G100+O100, "") | W100: =IFERROR(I100+P100, "") -> 214.25 | X100: =J100+Q100 -> 87 | Y100: =IFERROR((I100+P100)*0.33+18, "") -> 88.7025 | Z100: =IF(J100=0,0,(J100+Q100)*0.33+18) -> 46.71 | AB100: =IF(OR(T100="", U100="", V100=""), "", MAX(S100,T100)*40%+U100*30%+V100*30%) | AC100: =IF(AB100="", "", MAX(Y100, Z100)-AB100) | AE100: =IFERROR(MIN((MAX(S100,T100)*70%+V100*30%), Z100), "") | AF100: =IF(AE100="", "", MAX(AB100, AC100)-AE100)
B101: 2010 | C101: 2 | D101: 4 | F101: 50 | I101: 178.6 | J101: 67 | M101: 53.686275 | N101: 23.388235 | O101: =IFERROR(M101*0.9, "") -> 48.317647 | P101: 31.8 | Q101: 20 | S101: =T101*S102/T102 -> 195.02779 | T101: =IF(F101=0, "", F101+N101) -> 73.388235 | U101: =IFERROR( E101+M101, "") | V101: =IFERROR( G101+O101, "") | W101: =IFERROR(I101+P101, "") -> 210.4 | X101: =J101+Q101 -> 87 | Y101: =IFERROR((I101+P101)*0.33+18, "") -> 87.432 | Z101: =IF(J101=0,0,(J101+Q101)*0.33+18) -> 46.71 | AB101: =IF(OR(T101="", U101="", V101=""), "", MAX(S101,T101)*40%+U101*30%+V101*30%) | AC101: =IF(AB101="", "", MAX(Y101, Z101)-AB101) | AE101: =IFERROR(MIN((MAX(S101,T101)*70%+V101*30%), Z101), "") | AF101: =IF(AE101="", "", MAX(AB101, AC101)-AE101)
B102: 2010 | C102: 2 | D102: 5 | F102: 50 | I102: 121.5 | J102: 67.625 | M102: 53.686275 | N102: 23.388235 | O102: =IFERROR(M102*0.9, "") -> 48.317647 | P102: 32.5 | Q102: 20 | S102: =T102*S103/T103 -> 195.02779 | T102: =IF(F102=0, "", F102+N102) -> 73.388235 | U102: =IFERROR( E102+M102, "") | V102: =IFERROR( G102+O102, "") | W102: =IFERROR(I102+P102, "") -> 154 | X102: =J102+Q102 -> 87.625 | Y102: =IFERROR((I102+P102)*0.33+18, "") -> 68.82 | Z102: =IF(J102=0,0,(J102+Q102)*0.33+18) -> 46.91625 | AB102: =IF(OR(T102="", U102="", V102=""), "", MAX(S102,T102)*40%+U102*30%+V102*30%) | AC102: =IF(AB102="", "", MAX(Y102, Z102)-AB102) | AE102: =IFERROR(MIN((MAX(S102,T102)*70%+V102*30%), Z102), "") | AF102: =IF(AE102="", "", MAX(AB102, AC102)-AE102)
...

Sheet Phosphate historical prices
C2: DAP | D2: DAP | E2: DAP | F2: DAP | G2: DAP | H2: DAP | I2: MAP | J2: MAP | K2: TSP | L2: TSP | M2: Phosphoric acid (100% P2O5) | N2: Phosphoric acid (100% P2O5) | O2: Phosphoric acid (100% P2O5) Non-food grade | P2: DAP | Q2: MAP
C3: NOLA | D3: Morocco | E3: Jordan | F3: Saudi Arabia | G3: India | H3: China | I3: Baltic/Black Sea | J3: Brazil | K3: Morocco | L3: Brazil | M3: North Africa | N3: India 30 days | O3: NW Europe | P3: US Gulf/Tampa | Q3: US Gulf/Tampa
C4: FOB | D4: FOB | E4: FOB | F4: FOB | G4: CFR | H4: FOB | I4: FOB | J4: CFR | K4: FOB | L4: CFR | M4: FOB | N4: CFR | O4: CFR | P4: FOB | Q4: FOB
C5: DAP FOB NOLA | D5: DAP FOB Morocco | E5: DAP FOB Jordan | F5: DAP FOB Saudi Arabia | G5: DAP CFR India | H5: DAP FOB China | I5: MAP FOB Baltic/Black Sea | J5: MAP CFR Brazil | K5: TSP FOB Morocco | L5: TSP CFR Brazil | M5: Phosphoric acid (100% P2O5) FOB North Africa | N5: Phosphoric acid (100% P2O5) CFR India 30 days | O5: Phosphoric acid (100% P2O5) Non-food grade CFR NW Europe | P5: DAP FOB US Gulf/Tampa | Q5: MAP FOB US Gulf/Tampa
B6: 2000 | C6: - | D6: 160.26136 | E6: 165.67941 | F6: - | G6: - | H6: - | I6: 147.45425 | J6: 167.81338 | K6: 129.14183 | L6: - | M6: 308.79808 | N6: 369.69231 | O6: 372.06731 | P6: 153.62303 | Q6: -
B7: 2001 | C7: - | D7: 151.95986 | E7: 161.45382 | F7: - | G7: - | H7: - | I7: 142.26821 | J7: 161.9113 | K7: 125.17439 | L7: - | M7: 290.75 | N7: 348.61458 | O7: 344.6875 | P7: 147.29451 | Q7: -
B8: 2002 | C8: - | D8: 158.11939 | E8: 169.43429 | F8: - | G8: 172.95299 | H8: - | I8: 146.18269 | J8: 168.70175 | K8: 126.67548 | L8: - | M8: 282.82692 | N8: 337.67308 | O8: 330.92308 | P8: 157.65946 | Q8: -
B9: 2003 | C9: 187.38785 | D9: 182.96078 | E9: 191.66667 | F9: - | G9: 199.61765 | H9: - | I9: 175.13725 | J9: 200.29412 | K9: 146.33333 | L9: - | M9: 288.27451 | N9: 340.76471 | O9: 332.96078 | P9: 178.56863 | Q9: -
B10: 2004 | C10: 227.93368 | D10: 233.92157 | E10: 252.94118 | F10: - | G10: 246.68627 | H10: - | I10: 215.33333 | J10: 249.29412 | K10: 175.13725 | L10: - | M10: 329.5098 | N10: 384.33333 | O10: 369.80392 | P10: 222.61538 | Q10: 227.85714
B11: 2005 | C11: 252.91307 | D11: 259.14 | E11: 277.08 | F11: - | G11: 289.02 | H11: - | I11: 234.7 | J11: 271.8 | K11: 186.18 | L11: - | M11: 373.56 | N11: 426.5 | O11: 428.46 | P11: 247.4902 | Q11: 247.04082
B12: 2006 | C12: 256.35039 | D12: 264.58 | E12: 278.8 | F12: - | G12: 297.4 | H12: - | I12: 247.24 | J12: 285 | K12: 192.1 | L12: - | M12: 389.5 | N12: 453.96 | O12: 452.14 | P12: 262.76923 | Q12: 260.06122
B13: 2007 | C13: 432.71289 | D13: 420.96 | E13: 417.14286 | F13: - | G13: 458.48649 | H13: - | I13: 410.62 | J13: 458.86 | K13: 343.58 | L13: - | M13: 483.5 | N13: 532.4 | O13: 545 | P13: 423.98039 | Q13: 401.21429
B14: 2008 | C14: 914.93179 | D14: 1054.9756 | E14: 1102.45 | F14: - | G14: 986.14286 | H14: - | I14: 934.54 | J14: 1105.0698 | K14: 924.68421 | L14: - | M14: 1905.76 | N14: 1714.2 | O14: 2062.8163 | P14: 978.32 | Q14: 1163.3548
B15: 2009 | C15: 323.63667 | D15: 336.6383 | E15: 327.11628 | F15: - | G15: 365.28846 | H15: - | I15: 331.90385 | J15: 356.75556 | K15: 258 | L15: - | M15: 540.30769 | N15: 619.13462 | O15: 715.08 | P15: 328.03774 | Q15: 323.47826
B16: 2010 | C16: 508.9051 | D16: 494.94231 | E16: 477.69231 | F16: - | G16: 469.46154 | H16: - | I16: 488.34615 | J16: 529.40385 | K16: 391.38462 | L16: - | M16: 668.94231 | N16: 742.5 | O16: 800.46154 | P16: 501.46154 | Q16: 501.11538
B17: 2011 | C17: 617.46247 | D17: 646.11538 | E17: 593.42308 | F17: 665.29412 | G17: 607.80769 | H17: 614.63462 | I17: 631.53846 | J17: 664.71154 | K17: 541.07692 | L17: - | M17: 978.46154 | N17: 993.84615 | O17: 1118.4038 | P17: 619.25 | Q17: 626.58824
B18: 2012 | C18: 539.39445 | D18: 556.36538 | E18: 561.61538 | F18: 557.5098 | G18: 576.75 | H18: 545.71154 | I18: 539.53846 | J18: 575.96154 | K18: 462.05769 | L18: - | M18: 930.28846 | N18: 909.30769 | O18: 1084.4231 | P18: 539.78846 | Q18: 557.19231
B19: 2013 | C19: 456.81028 | D19: 471.11538 | E19: 461.69231 | F19: 456.11538 | G19: 466.11538 | H19: 442.46154 | I19: 455.38462 | J19: 480.48077 | K19: 381.65385 | L19: - | M19: 778.82692 | N19: 714.84615 | O19: 941.44231 | P19: 445.86538 | Q19: 452.98077
B20: 2014 | C20: 489.16547 | D20: 498.05769 | E20: 463.67308 | F20: 463.01923 | G20: 460.76923 | H20: 448.82692 | I20: 468.94231 | J20: 492.63462 | K20: 391.40385 | L20: 401.26923 | M20: 727.61538 | N20: 715.26923 | O20: 879.84615 | P20: 471.96154 | Q20: 478.07692
B21: 2015 | C21: 458.67571 | D21: 492.28302 | E21: 466.11321 | F21: 461.92453 | G21: 465 | H21: 452.32075 | I21: 462.66038 | J21: 469.77358 | K21: 387.41509 | L21: 373.07547 | M21: 783.58491 | N21: 798.58491 | O21: 945.37736 | P21: 458 | Q21: 459.22642
B22: 2016 | C22: 349.58867 | D22: 361.19231 | E22: 346.86538 | F22: 342.51923 | G22: 343.75 | H22: 332.09615 | I22: 338.28846 | J22: 350.38462 | K22: 288.73077 | L22: 288.28846 | M22: 699.28846 | N22: 626.48077 | O22: 825.88462 | P22: 345.07692 | Q22: 345.40385
B23: 2017 | C23: 356.70277 | D23: 367.82353 | E23: 349.54902 | F23: 363.29412 | G23: 362.78431 | H23: 356.98039 | I23: 349.78431 | J23: 369.17647 | K23: 277.19608 | L23: 282.94118 | M23: 602.11765 | N23: 566.82353 | O23: 705.35294 | P23: 354.03922 | Q23: 354.60784
B24: 2018 | C24: 435.11252 | D24: 428.82353 | E24: 411.01961 | F24: 418.21569 | G24: 423 | H24: 411.96078 | I24: 412.52941 | J24: 438.43137 | K24: 338.07843 | L24: 350.01961 | M24: 764.4902 | N24: 732.43137 | O24: 855.05882 | P24: 419.09804 | Q24: 418.2549
B25: 2019 | C25: 339.36485 | D25: 362.92157 | E25: 349.29412 | F25: 360.58824 | G25: 361.05882 | H25: 348.68627 | I25: 336.27451 | J25: 360.72549 | K25: 313.29412 | L25: 311.62745 | M25: 744.96078 | N25: 690.76471 | O25: 852.05882 | P25: 345.5098 | Q25: 345.47059
B26: 2020 | C26: 343.80036 | D26: 322.30769 | E26: 316.75 | F26: 323.13462 | G26: 331.38462 | H26: 322.23077 | I26: 317.03846 | J26: 337.11538 | K26: 249.15385 | L26: 251.48077 | M26: 687 | N26: 627.75 | O26: 791.55769 | P26: 322.75 | Q26: 321.40385
B27: 2021 | C27: 664.05085 | D27: 650.76471 | E27: 619.93333 | F27: 612.39216 | G27: 618.15686 | H27: 566.31818 | I27: 651.19608 | J27: 691.11765 | K27: 549.23529 | L27: 562.13725 | M27: 1113.902 | N27: 1072.8235 | O27: 1254.1579 | P27: 641.11765 | Q27: 656.46
B28: 2022 | C28: 848.10948 | D28: 968.90196 | E28: 897.96078 | F28: 891.31373 | G28: 875.98039 | H28: 800.78571 | I28: 849.27451 | J28: 911.21569 | K28: 820.94118 | L28: 801.66667 | M28: 1617.5686 | N28: 1540.7843 | O28: 1712.6471 | P28: 898.78431 | Q28: 902.52941
B29: 2023 | C29: 604.3842 | D29: 588.72549 | E29: 557.17647 | F29: 564.31373 | G29: 568.80392 | H29: 556.52941 | I29: 516.72549 | J29: 556.88235 | K29: 449.39216 | L29: 434.35294 | M29: 1011.2941 | N29: 963.33333 | O29: 1151.1373 | P29: 560.27451 | Q29: 552.15686
B30: 2024 | C30: 620.01427 | D30: 585.54902 | E30: 581.98039 | F30: 590.54902 | G30: 587.4902 | H30: 578.84444 | I30: 554.76471 | J30: 602.62745 | K30: 436.07843 | L30: 465.05882 | M30: 994.8 | N30: 979.84314 | O30: 1117.0588 | P30: 560 | Q30: 560
B31: 2025 | C31: 768.9175 | D31: 711.31581 | E31: 712.79613 | F31: 707.28352 | G31: 719.76538 | H31: 703.39359 | I31: 643.65346 | J31: 690.28846 | K31: 520.54204 | L31: 556.1859 | M31: 1241.4936 | N31: 1189 | O31: 1277.7616
B32: 2026 | C32: 735.41419 | D32: 681.48333 | E32: 675.35556 | F32: 663.00721 | G32: 699.26667 | H32: 680.26667 | I32: 611.46179 | J32: 668.33333 | K32: 502.43006 | L32: 528.75 | M32: 1244.6548 | N32: 1200 | O32: 1368.3766
B33: 2027 | C33: 678.88993 | D33: 629.38889 | E33: 617.25833 | F33: 614.23491 | G33: 653.84767 | H33: 632.11583 | I33: 581.80452 | J33: 635.63044 | K33: 486.71209 | L33: 508.95956 | M33: 1231.8886 | N33: 1192.3937 | O33: 1354.0114
B34: 2028 | C34: 635.78578 | D34: 594.50002 | E34: 584.12857 | F34: 581.92523 | G34: 610.20233 | H34: 599.505 | I34: 560.62028 | J34: 611.99582 | K34: 471.78529 | L34: 494.49045 | M34: 1142.9244 | N34: 1107.9364 | O34: 1260.3934
B35: 2029 | C35: 591.73817 | D35: 561.00871 | E35: 553.37073 | F35: 552.41348 | G35: 568.69042 | H35: 561.83037 | I35: 530.88171 | J35: 578.50923 | K35: 445.5145 | L35: 468.76322 | M35: 1051.2796 | N35: 1024.7139 | O35: 1163.1748
B36: 2030 | C36: 561.90093 | D36: 538.7978 | E36: 533.0051 | F36: 532.72286 | G36: 541.8769 | H36: 537.49544 | I36: 508.91313 | J36: 553.80148 | K36: 421.71637 | L36: 445.79866 | M36: 998.30959 | N36: 976.89824 | O36: 1106.924

Sheet Phosphate monthly prices
D1: DAP Bulk FOB | G1: DAP Bulk FOB | J1: DAP Bulk FOB | M1: DAP Bulk FOB | P1: DAP Bulk FOB | S1: DAP Bulk FOB | V1: DAP Bulk FOB | Y1: DAP Bulk FOB | AB1: DAP Bulk FOB | AE1: DAP Bulk FOB | AH1: DAP Bulk FOB | AK1: DAP Bulk FOB | AN1: DAP Bulk FOB | AQ1: DAP Bulk FOB | AT1: DAP Bulk FOB | AW1: DAP Bulk FOB | AZ1: DAP Bulk FOB | BC1: DAP Bulk FOB | BF1: DAP Bulk FOB | BI1: DAP Bulk FOB | BL1: DAP Bulk FOB | BO1: DAP Bulk FOB | BR1: DAP Bulk FOB | BU1: DAP Bulk CFR | BX1: DAP Bulk CFR | CA1: DAP Bulk CFR | CD1: DAP Bagged CFR | CG1: DAP Bulk CFR | CJ1: DAP Bagged CPT | CM1: DAP Bagged EXW | CP1: DAP Bulk FCA | CS1: DAP Bulk DEL | CV1: DAP Bulk DEL | CY1: MAP Granular Bulk FOB | DB1: MAP Granular Bulk FOB | DE1: MAP Granular Bulk FOB | DH1: MAP Granular Bulk FOB | DK1: MAP Granular Bulk FOB | DN1: MAP Granular Bulk FOB | DQ1: MAP Granular Bulk FOB | DT1: MAP Bulk FOB | DW1: MAP Granular Bulk FOB | DZ1: MAP Bulk FOB | EC1: MAP Granular Bulk FOB | EF1: MAP Granular Bulk FOB | EI1: MAP Granular Bulk FOB | EL1: MAP Granular Bulk FOB | EO1: MAP Bagged EXW | ER1: MAP Bagged EXW | EU1: MAP Granular Bulk CFR | EX1: MAP Granular Bulk CFR | FA1: MAP Granular Bulk CFR | FD1: MAP Granular Bulk DEL | FG1: TSP Granular Bulk FOB | FJ1: TSP Granular Bulk FOB | FM1: TSP Granular Bulk FCA | FP1: TSP Granular Bulk FOB | FS1: TSP Bulk FOB | FV1: TSP Granular Bulk FOB | FY1: TSP Granular Bulk CFR | GB1: Phosphoric Acid Bulk FOB | GE1: Phosphoric Acid Bulk CFR | GH1: Phosphoric Acid Bulk CFR | GK1: Phosphoric Acid Bulk CFR | GN1: Phosphoric Acid Bulk CFR | GQ1: Phosphoric Acid Bulk FOB | GT1: Phosphoric Acid Bulk CFR | GW1: Phosphoric Acid Bulk FOB | GZ1: Phosphate Rock Bulk FOB | HC1: Phosphate Rock Bulk CFR | HF1: Phosphate Rock Bulk CFR | HI1: Phosphate Rock Bulk CFR | HL1: Phosphate Rock Bulk FOB | HO1: Phosphate Rock Bulk FOB | HR1: Phosphate Rock Bulk FOB | HU1: Phosphate Rock Bulk FOB | HX1: Phosphate Rock Bulk FOB | IA1: Phosphate Rock Bulk FOB
D2: US Gulf/Tampa Spot | G2: US Central Florida Spot | J2: US New Orleans barge Spot | M2: US Midwest Spot | P2: US Midwest East Spot | S2: US Midwest West Spot | V2: US Southern Plains Spot | Y2: US South Spot | AB2: US Twin Cities Spot | AE2: US Tulsa Spot | AH2: US Cincinnati Spot | AK2: Mexico Spot/Contract | AN2: NW Mexico Spot | AQ2: US Gulf 2x4mm Spot | AT2: Argentina Spot | AW2: Baltic/Black Sea Spot | AZ2: North Africa Spot | BC2: Tunisia Spot | BF2: Morocco Spot | BI2: Jordan Spot | BL2: Saudi Arabia Spot | BO2: Australia Spot | BR2: China Spot | BU2: India Spot | BX2: Pakistan Spot | CA2: China Spot | CD2: China Spot | CG2: Argentina/Uruguay Spot | CJ2: China wholesale Spot | CM2: China (excludes export sales) Spot | CP2: Terneuzen/Ghent Spot | CS2: US California Spot | CV2: US Northwest Spot | CY2: Baltic/Black Sea Spot | DB2: US New Orleans barge Spot | DE2: US Twin Cities Spot | DH2: US Tulsa Spot | DK2: US Cincinnati Spot | DN2: US Midwest Spot | DQ2: US Southern Plains Spot | DT2: US Central Florida Spot | DW2: US Gulf/Tampa Spot | DZ2: Brazil plant Spot | EC2: Morocco Spot | EF2: Mexico Spot/Contract | EI2: China 11-44 Spot | EL2: Saudi Arabia Spot | EO2: China 11-44-0 (excludes export sales) Spot | ER2: China 10-50-0 (excludes export sales) Spot | EU2: Argentina Spot | EX2: Brazil Spot | FA2: Brazil 11-44 Spot | FD2: Western Canada Spot | FG2: Tunisia Spot | FJ2: Morocco Spot | FM2: Benelux Spot | FP2: US Central Florida Spot | FS2: Tampa/US gulf Spot | FV2: China Spot | FY2: Brazil Spot | GB2: North Africa Quarterly 100% P2O5 Contract | GE2: India Quarterly 100% P2O5 Contract | GH2: NW Europe Quarterly 100% P2O5 Spot/Contract | GK2: NW Europe (non-food grade) Quarterly 100% P2O5 Spot/Contract | GN2: Mediterranean 100% P2O5 Spot | GQ2: US Tampa Spot | GT2: Brazil Quarterly 100% P2O5 Spot/Contract | GW2: US Gulf 100% P205 Spot | GZ2: Morocco (68-72% BPL) Spot/Contract | HC2: India (71-75% BPL) Spot/Contract | HF2: India (71-80% BPL) Spot/Contract | HI2: India (65-70% BPL) Spot/Contract | HL2: Egypt (60-68% BPL) Spot/Contract | HO2: Jordan Quarterly (66-72% BPL) Contract | HR2: Jordan Quarterly (73-75% BPL) Contract | HU2: Russia (78-87% BPL) Spot/Contract | HX2: Peru (63-68% BPL) Spot/Contract | IA2: Algeria (63-66% BPL) Spot/Contract
D3: USD/t | G3: USD/st | J3: USD/st | M3: USD/st | P3: USD/st | S3: USD/st | V3: USD/st | Y3: USD/st | AB3: USD/st | AE3: USD/st | AH3: USD/st | AK3: USD/t | AN3: MXN/t | AQ3: USD/t | AT3: ARS/t | AW3: USD/t | AZ3: USD/t | BC3: USD/t | BF3: USD/t | BI3: USD/t | BL3: USD/t | BO3: USD/t | BR3: USD/t | BU3: USD/t | BX3: USD/t | CA3: USD/t | CD3: RMB/t | CG3: USD/t | CJ3: RMB/t | CM3: RMB/t | CP3: USD/t | CS3: USD/st | CV3: USD/st | CY3: USD/t | DB3: USD/st | DE3: USD/st | DH3: USD/st | DK3: USD/st | DN3: USD/st | DQ3: USD/st | DT3: USD/st | DW3: USD/t | DZ3: BRL/t | EC3: USD/t | EF3: USD/t | EI3: USD/t | EL3: USD/t | EO3: RMB/t | ER3: RMB/t | EU3: USD/t | EX3: USD/t | FA3: USD/t | FD3: CAD/t | FG3: USD/t | FJ3: USD/t | FM3: USD/t | FP3: USD/st | FS3: USD/t | FV3: USD/t | FY3: USD/t | GB3: USD/t | GE3: USD/t | GH3: USD/t | GK3: USD/t | GN3: USD/t | GQ3: USD/t | GT3: USD/t | GW3: USD/t | GZ3: USD/t | HC3: USD/t | HF3: USD/t | HI3: USD/t | HL3: USD/t | HO3: USD/t | HR3: USD/t | HU3: USD/t | HX3: USD/t | IA3: USD/t
A4: Year | B4: Quarter | C4: Month | D4: Max | E4: Min | F4: Avg | G4: Max | H4: Min | I4: Avg | J4: Max | K4: Min | L4: Avg | M4: Max | N4: Min | O4: Avg | P4: Max | Q4: Min | R4: Avg | S4: Max | T4: Min | U4: Avg | V4: Max | W4: Min | X4: Avg | Y4: Max | Z4: Min | AA4: Avg | AB4: Max | AC4: Min | AD4: Avg | AE4: Max | AF4: Min | AG4: Avg | AH4: Max | AI4: Min | AJ4: Avg | AK4: Max | AL4: Min | AM4: Avg | AN4: Max | AO4: Min | AP4: Avg | AQ4: Max | AR4: Min | AS4: Avg | AT4: Max | AU4: Min | AV4: Avg | AW4: Max | AX4: Min | AY4: Avg | AZ4: Max | BA4: Min | BB4: Avg | BC4: Max | BD4: Min | BE4: Avg | BF4: Max | BG4: Min | BH4: Avg | BI4: Max | BJ4: Min | BK4: Avg | BL4: Max | BM4: Min | BN4: Avg | BO4: Max | BP4: Min | BQ4: Avg | BR4: Max | BS4: Min | BT4: Avg | BU4: Max | BV4: Min | BW4: Avg | BX4: Max | BY4: Min | BZ4: Avg | CA4: Max | CB4: Min | CC4: Avg | CD4: Max | CE4: Min | CF4: Avg | CG4: Max | CH4: Min | CI4: Avg | CJ4: Max | CK4: Min | CL4: Avg | CM4: Max | CN4: Min | CO4: Avg | CP4: Max | CQ4: Min | CR4: Avg | CS4: Max | CT4: Min | CU4: Avg | CV4: Max | CW4: Min | CX4: Avg | CY4: Max | CZ4: Min | DA4: Avg | DB4: Max | DC4: Min | DD4: Avg | DE4: Max | DF4: Min | DG4: Avg | DH4: Max | DI4: Min | DJ4: Avg | DK4: Max | DL4: Min | DM4: Avg | DN4: Max | DO4: Min | DP4: Avg | DQ4: Max | DR4: Min | DS4: Avg | DT4: Max | DU4: Min | DV4: Avg | DW4: Max | DX4: Min | DY4: Avg | DZ4: Max | EA4: Min | EB4: Avg | EC4: Max | ED4: Min | EE4: Avg | EF4: Max | EG4: Min | EH4: Avg | EI4: Max | EJ4: Min | EK4: Avg | EL4: Max | EM4: Min | EN4: Avg | EO4: Max | EP4: Min | EQ4: Avg | ER4: Max | ES4: Min | ET4: Avg | EU4: Max | EV4: Min | EW4: Avg | EX4: Max | EY4: Min | EZ4: Avg | FA4: Max | FB4: Min | FC4: Avg | FD4: Max | FE4: Min | FF4: Avg | FG4: Max | FH4: Min | FI4: Avg | FJ4: Max | FK4: Min | FL4: Avg | FM4: Max | FN4: Min | FO4: Avg | FP4: Max | FQ4: Min | FR4: Avg | FS4: Max | FT4: Min | FU4: Avg | FV4: Max | FW4: Min | FX4: Avg | FY4: Max | FZ4: Min | GA4: Avg | GB4: Max | GC4: Min | GD4: Avg | GE4: Max | GF4: Min | GG4: Avg | GH4: Max | GI4: Min | GJ4: Avg | GK4: Max | GL4: Min | GM4: Avg | GN4: Max | GO4: Min | GP4: Avg | GQ4: Max | GR4: Min | GS4: Avg | GT4: Max | GU4: Min | GV4: Avg | GW4: Max | GX4: Min | GY4: Avg | GZ4: Max | HA4: Min | HB4: Avg | HC4: Max | HD4: Min | HE4: Avg | HF4: Max | HG4: Min | HH4: Avg | HI4: Max | HJ4: Min | HK4: Avg | HL4: Max | HM4: Min | HN4: Avg | HO4: Max | HP4: Min | HQ4: Avg | HR4: Max | HS4: Min | HT4: Avg | HU4: Max | HV4: Min | HW4: Avg | HX4: Max | HY4: Min | HZ4: Avg | IA4: Max | IB4: Min | IC4: Avg
A5: 1987 | B5: 2 | C5: 4 | AZ5: 175 | BA5: 170 | BB5: 173 | BF5: 175 | BG5: 170 | BH5: 173 | BI5: 180 | BJ5: 170 | BK5: 175 | CP5: 205 | CQ5: 200 | CR5: 203 | FJ5: 146 | FK5: 143 | FL5: 145 | FS5: 135 | FT5: 130 | FU5: 133 | GB5: 260 | GC5: 250 | GD5: 255 | GE5: 325 | GF5: 325 | GG5: 325 | GH5: 325 | GI5: 315 | GJ5: 320 | GW5: 255 | GX5: 250 | GY5: 253
A6: 1987 | B6: 2 | C6: 5 | AZ6: 175 | BA6: 170 | BB6: 173 | BF6: 175 | BG6: 170 | BH6: 173 | BI6: 168.75 | BJ6: 162.5 | BK6: 166 | CP6: 205 | CQ6: 200 | CR6: 203 | FJ6: 146 | FK6: 143 | FL6: 145 | FS6: 136.5 | FT6: 131 | FU6: 134 | GB6: 260 | GC6: 248 | GD6: 254 | GE6: 325 | GF6: 325 | GG6: 325 | GH6: 325 | GI6: 315 | GJ6: 320 | GW6: 255 | GX6: 250 | GY6: 253
A7: 1987 | B7: 2 | C7: 6 | AZ7: 187.5 | BA7: 180 | BB7: 184 | BF7: 187.5 | BG7: 180 | BH7: 184 | BI7: 180 | BJ7: 173.75 | BK7: 177.25 | CP7: 205 | CQ7: 200 | CR7: 203 | FJ7: 146 | FK7: 143 | FL7: 145 | FS7: 141.25 | FT7: 137 | FU7: 139.5 | GB7: 260 | GC7: 248 | GD7: 254 | GE7: 325 | GF7: 325 | GG7: 325 | GH7: 325 | GI7: 315 | GJ7: 320 | GW7: 255 | GX7: 250 | GY7: 253
A8: 1987 | B8: 3 | C8: 7 | AZ8: 199 | BA8: 193 | BB8: 196.4 | BF8: 199 | BG8: 193 | BH8: 196.4 | BI8: 196 | BJ8: 191 | BK8: 194 | CP8: 205 | CQ8: 200 | CR8: 203 | FJ8: 147.6 | FK8: 144.4 | FL8: 146.4 | FS8: 146.6 | FT8: 143.8 | FU8: 145.4 | GB8: 260 | GC8: 248 | GD8: 254 | GE8: 325 | GF8: 325 | GG8: 325 | GH8: 327 | GI8: 319 | GJ8: 323 | GW8: 255 | GX8: 250 | GY8: 253
A9: 1987 | B9: 3 | C9: 8 | AZ9: 210 | BA9: 203.75 | BB9: 207.25 | BF9: 210 | BG9: 203.75 | BH9: 207.25 | BI9: 208.75 | BJ9: 203.75 | BK9: 206.75 | FJ9: 154.25 | FK9: 151 | FL9: 153 | FS9: 153.25 | FT9: 149.75 | FU9: 151.75 | GB9: 260 | GC9: 254 | GD9: 257.5 | GE9: 325 | GF9: 325 | GG9: 325 | GH9: 335 | GI9: 325 | GJ9: 330 | GW9: 258 | GX9: 255 | GY9: 257
A10: 1987 | B10: 3 | C10: 9 | AZ10: 210 | BA10: 205 | BB10: 208 | BF10: 210 | BG10: 205 | BH10: 208 | BI10: 207.5 | BJ10: 202.5 | BK10: 205.5 | CP10: 215 | CQ10: 215 | CR10: 215 | FJ10: 155 | FK10: 152 | FL10: 154 | FS10: 152.25 | FT10: 148.75 | FU10: 150.75 | GB10: 260 | GC10: 251 | GD10: 256 | GE10: 325 | GF10: 325 | GG10: 325 | GH10: 335 | GI10: 325 | GJ10: 330 | GW10: 258 | GX10: 255 | GY10: 257
A11: 1987 | B11: 4 | C11: 10 | AZ11: 207.2 | BA11: 201 | BB11: 204.6 | BF11: 207.2 | BG11: 201 | BH11: 204.6 | BI11: 198.8 | BJ11: 195 | BK11: 197.2 | CP11: 215 | CQ11: 215 | CR11: 215 | FJ11: 154.6 | FK11: 151.6 | FL11: 153.6 | FS11: 148.2 | FT11: 144.8 | FU11: 147 | GB11: 256 | GC11: 251 | GD11: 253.6 | GE11: 350 | GF11: 350 | GG11: 350 | GH11: 328 | GI11: 322 | GJ11: 325.4 | GW11: 255.6 | GX11: 251 | GY11: 253.8
A12: 1987 | B12: 4 | C12: 11 | AZ12: 207.75 | BA12: 201.25 | BB12: 205 | BF12: 207.75 | BG12: 201.25 | BH12: 205 | BI12: 200.5 | BJ12: 196.25 | BK12: 198.75 | CP12: 215 | CQ12: 215 | CR12: 215 | FJ12: 153 | FK12: 150 | FL12: 152 | FS12: 145 | FT12: 142.5 | FU12: 144 | GB12: 255 | GC12: 251 | GD12: 253 | GE12: 350 | GF12: 350 | GG12: 350 | GH12: 330 | GI12: 325 | GJ12: 328 | GW12: 255 | GX12: 250 | GY12: 253
A13: 1987 | B13: 4 | C13: 12 | AZ13: 217.5 | BA13: 212.5 | BB13: 215.5 | BF13: 217.5 | BG13: 212.5 | BH13: 215.5 | BI13: 215 | BJ13: 211 | BK13: 213.5 | CP13: 245 | CQ13: 240 | CR13: 243 | FJ13: 157 | FK13: 152.75 | FL13: 155.25 | FS13: 148 | FT13: 144 | FU13: 146.5 | GB13: 275 | GC13: 270.5 | GD13: 273 | GE13: 367.5 | GF13: 367.5 | GG13: 367.5 | GH13: 347.5 | GI13: 333.75 | GJ13: 340.75 | GW13: 275 | GX13: 270 | GY13: 273
A14: 1988 | B14: 1 | C14: 1 | AZ14: 226.25 | BA14: 217.25 | BB14: 222.25 | BF14: 226.25 | BG14: 217.25 | BH14: 222.25 | BI14: 223.75 | BJ14: 220.25 | BK14: 222.25 | CP14: 243.75 | CQ14: 238 | CR14: 241.25 | FJ14: 165 | FK14: 160 | FL14: 163 | FS14: 156.5 | FT14: 154 | FU14: 155.5 | GB14: 295 | GC14: 290 | GD14: 293 | GE14: 385 | GF14: 385 | GG14: 385 | GH14: 362.5 | GI14: 350 | GJ14: 356.5 | GW14: 295 | GX14: 290 | GY14: 293
A15: 1988 | B15: 1 | C15: 2 | AZ15: 220 | BA15: 210 | BB15: 215 | BF15: 220 | BG15: 210 | BH15: 215 | BI15: 218 | BJ15: 217 | BK15: 218 | CP15: 240 | CQ15: 232 | CR15: 236 | FJ15: 162.5 | FK15: 157.25 | FL15: 160.25 | FS15: 156.75 | FT15: 153.5 | FU15: 155.5 | GB15: 302.5 | GC15: 293.75 | GD15: 298.25 | GE15: 385 | GF15: 385 | GG15: 385 | GH15: 367.5 | GI15: 362.5 | GJ15: 365.5 | GW15: 298.75 | GX15: 318.75 | GY15: 309.25
A16: 1988 | B16: 1 | C16: 3 | AZ16: 220 | BA16: 215 | BB16: 218 | BF16: 220 | BG16: 215 | BH16: 218 | BI16: 210 | BJ16: 206 | BK16: 208.4 | CP16: 234 | CQ16: 227.8 | CR16: 231.2 | FJ16: 159.6 | FK16: 155 | FL16: 157.6 | FS16: 156 | FT16: 152 | FU16: 154 | GB16: 310 | GC16: 305 | GD16: 308 | GE16: 385 | GF16: 385 | GG16: 385 | GH16: 370 | GI16: 365 | GJ16: 368 | GW16: 310 | GX16: 305 | GY16: 308
A17: 1988 | B17: 2 | C17: 4 | AZ17: 213.75 | BA17: 208.75 | BB17: 211.75 | BF17: 213.75 | BG17: 208.75 | BH17: 211.75 | BI17: 206.5 | BJ17: 202 | BK17: 204.5 | CP17: 230 | CQ17: 225 | CR17: 228 | FJ17: 163.5 | FK17: 156.5 | FL17: 160 | FS17: 156 | FT17: 152 | FU17: 154 | GB17: 332.5 | GC17: 327.5 | GD17: 330.5 | GE17: 385 | GF17: 385 | GG17: 385 | GH17: 370 | GI17: 365 | GJ17: 368 | GW17: 310 | GX17: 305 | GY17: 308
A18: 1988 | B18: 2 | C18: 5 | AZ18: 213 | BA18: 207.5 | BB18: 210.5 | BF18: 213 | BG18: 207.5 | BH18: 210.5 | BI18: 205 | BJ18: 200 | BK18: 203 | CP18: 230 | CQ18: 225 | CR18: 228 | FJ18: 164 | FK18: 158.5 | FL18: 161.5 | FS18: 156 | FT18: 152 | FU18: 154 | GB18: 340 | GC18: 335 | GD18: 338 | GE18: 385 | GF18: 385 | GG18: 385 | GH18: 370 | GI18: 365 | GJ18: 368 | GW18: 325 | GX18: 320 | GY18: 323
A19: 1988 | B19: 2 | C19: 6 | AZ19: 216 | BA19: 211.6 | BB19: 214.2 | BF19: 216 | BG19: 211.6 | BH19: 214.2 | BI19: 218 | BJ19: 213 | BK19: 216 | CP19: 230 | CQ19: 225 | CR19: 228 | FJ19: 163 | FK19: 160 | FL19: 162 | FS19: 156.8 | FT19: 152.6 | FU19: 154.8 | GB19: 340 | GC19: 335 | GD19: 338 | GE19: 417.8 | GF19: 417.8 | GG19: 417.8 | GH19: 370 | GI19: 365 | GJ19: 368 | GW19: 330 | GX19: 325 | GY19: 328
A20: 1988 | B20: 3 | C20: 7 | AZ20: 220 | BA20: 215 | BB20: 218 | BF20: 220 | BG20: 215 | BH20: 218 | BI20: 222.5 | BJ20: 218.5 | BK20: 221 | CP20: 235 | CQ20: 230 | CR20: 233 | FJ20: 170 | FK20: 163 | FL20: 167 | FS20: 160 | FT20: 155 | FU20: 158 | GB20: 355 | GC20: 350 | GD20: 353 | GE20: 426 | GF20: 426 | GG20: 426 | GH20: 400 | GI20: 390 | GJ20: 395 | GW20: 355 | GX20: 350 | GY20: 353
A21: 1988 | B21: 3 | C21: 8 | AZ21: 220 | BA21: 215 | BB21: 218 | BF21: 220 | BG21: 215 | BH21: 218 | BI21: 220 | BJ21: 217 | BK21: 219 | CP21: 240 | CQ21: 235 | CR21: 238 | FJ21: 167.5 | FK21: 163 | FL21: 165.5 | FS21: 161.5 | FT21: 157.5 | FU21: 160 | GB21: 355 | GC21: 350 | GD21: 353 | GE21: 426 | GF21: 426 | GG21: 426 | GH21: 400 | GI21: 390 | GJ21: 395 | GW21: 355 | GX21: 350 | GY21: 353
... A43: 1990 | B43: 2 | C43: 6 | AZ43: 190 | BA43: 180 | BB43: 185 | BF43: 190 | BG43: 180 | BH43: 185 | BI43: 180 | BJ43: 175 | BK43: 178 | CP43: 185 | CQ43: 179 | CR43: 182 | FJ43: 139 | FK43: 133.25 | FL43: 136.5 | FS43: 130.5 | FT43: 128 | FU43: 129.25 | GB43: 325 | GC43: 305 | GD43: 315 | GE43: 377 | GF43: 376 | GG43: 377 | GH43: 360 | GI43: 350 | GJ43: 355 | GW43: 285 | GX43: 278 | GY43: 282
A44: 1990 | B44: 3 | C44: 7 | D44: 179.33333 | E44: 176.33333 | F44: 178.33333 | G44: 150 | H44: 147 | I44: 149 | J44: 161.66667 | K44: 159.66667 | L44: 160.66667 | P44: 174.33333 | Q44: 172 | R44: 173.33333 | S44: 170 | T44: 168 | U44: 169 | AZ44: 193.75 | BA44: 187.5 | BB44: 191 | BF44: 193.75 | BG44: 187.5 | BH44: 191 | BI44: 195 | BJ44: 190 | BK44: 193 | CP44: 203.75 | CQ44: 194.75 | CR44: 199.25 | CS44: 210 | CT44: 209 | CU44: 210 | CV44: 205 | CW44: 205 | CX44: 205 | DT44: 157.33333 | DU44: 153.66667 | DV44: 155.66667 | FJ44: 143.5 | FK44: 140 | FL44: 142 | FP44: 123.33333 | FQ44: 118.33333 | FR44: 121.33333 | FS44: 132 | FT44: 129.5 | FU44: 130.75 | GB44: 325 | GC44: 305 | GD44: 315 | GE44: 377 | GF44: 376 | GG44: 377 | GH44: 360 | GI44: 350 | GJ44: 355 | GW44: 300 | GX44: 295 | GY44: 298
A45: 1990 | B45: 3 | C45: 8 | D45: 175.25 | E45: 172.25 | F45: 174.25 | G45: 151.5 | H45: 149 | I45: 150.5 | J45: 160.5 | K45: 159 | L45: 160 | P45: 174.25 | Q45: 171.25 | R45: 173.25 | S45: 170.25 | T45: 168.25 | U45: 169.25 | AZ45: 195.4 | BA45: 191 | BB45: 193.6 | BF45: 195.4 | BG45: 191 | BH45: 193.6 | BI45: 195 | BJ45: 190 | BK45: 193 | CP45: 212 | CQ45: 202 | CR45: 207 | CS45: 218.75 | CT45: 211.25 | CU45: 215 | CV45: 205 | CW45: 205 | CX45: 205 | DT45: 161.25 | DU45: 156.5 | DV45: 159 | FJ45: 146.6 | FK45: 141 | FL45: 144.2 | FP45: 129.25 | FQ45: 126 | FR45: 128 | FS45: 138.8 | FT45: 132.4 | FU45: 135.6 | GB45: 325 | GC45: 305 | GD45: 315 | GE45: 377 | GF45: 376 | GG45: 377 | GH45: 360 | GI45: 350 | GJ45: 355 | GW45: 300 | GX45: 295 | GY45: 298
A46: 1990 | B46: 3 | C46: 9 | D46: 182 | E46: 176.75 | F46: 179.5 | G46: 155.25 | H46: 151.5 | I46: 153.75 | J46: 166 | K46: 164.75 | L46: 165.75 | P46: 176 | Q46: 173.75 | R46: 175 | S46: 173.25 | T46: 170.5 | U46: 172.25 | AZ46: 199.5 | BA46: 196 | BB46: 198 | BF46: 199.5 | BG46: 196 | BH46: 198 | BI46: 195 | BJ46: 188.75 | BK46: 192.25 | CP46: 217.5 | CQ46: 210 | CR46: 214 | CS46: 227.5 | CT46: 210 | CU46: 218.75 | CV46: 195 | CW46: 180 | CX46: 188 | DT46: 168.5 | DU46: 161 | DV46: 164.75 | FJ46: 152.5 | FK46: 147.5 | FL46: 150.5 | FP46: 131.25 | FQ46: 128.25 | FR46: 130 | FS46: 147.5 | FT46: 141 | FU46: 144.5 | GB46: 327.5 | GC46: 305 | GD46: 316.5 | GE46: 392.75 | GF46: 376 | GG46: 384.75 | GH46: 372.5 | GI46: 356.5 | GJ46: 364.5 | GW46: 305 | GX46: 296.25 | GY46: 301
A47: 1990 | B47: 4 | C47: 10 | D47: 189 | E47: 185.75 | F47: 187.75 | G47: 159.25 | H47: 155.25 | I47: 157.75 | J47: 165.75 | K47: 164.25 | L47: 165.5 | P47: 179.5 | Q47: 175.25 | R47: 177.75 | S47: 180 | T47: 176 | U47: 178.25 | AZ47: 208.75 | BA47: 203.25 | BB47: 206.5 | BF47: 208.75 | BG47: 203.25 | BH47: 206.5 | BI47: 200 | BJ47: 197.25 | BK47: 198.75 | CP47: 226.25 | CQ47: 223.25 | CR47: 225.25 | CS47: 230 | CT47: 210 | CU47: 220 | CV47: 194 | CW47: 180 | CX47: 187.33333 | DT47: 169 | DU47: 163 | DV47: 166 | FJ47: 159.5 | FK47: 152.5 | FL47: 156.25 | FP47: 139.25 | FQ47: 136.75 | FR47: 138.25 | FS47: 153.75 | FT47: 145.25 | FU47: 149.75 | GB47: 330 | GC47: 305 | GD47: 318 | GE47: 410 | GF47: 376 | GG47: 393 | GH47: 410 | GI47: 376 | GJ47: 393 | GW47: 310 | GX47: 300 | GY47: 305
A48: 1990 | B48: 4 | C48: 11 | D48: 187.4 | E48: 185 | F48: 186.4 | G48: 157.4 | H48: 154.2 | I48: 155.8 | J48: 165.4 | K48: 162.8 | L48: 164.4 | P48: 180 | Q48: 175.8 | R48: 178.2 | S48: 180 | T48: 176.4 | U48: 178.2 | AZ48: 213.8 | BA48: 208 | BB48: 211.2 | BF48: 213.8 | BG48: 208 | BH48: 211.2 | BI48: 200 | BJ48: 198 | BK48: 199 | CP48: 228.4 | CQ48: 224 | CR48: 226.6 | CS48: 230 | CT48: 210 | CU48: 220 | CV48: 205 | CW48: 190 | CX48: 198 | DT48: 169 | DU48: 163 | DV48: 166 | FJ48: 163 | FK48: 155 | FL48: 159 | FP48: 139.6 | FQ48: 138 | FR48: 138.8 | FS48: 155 | FT48: 150 | FU48: 153 | GB48: 330 | GC48: 305 | GD48: 318 | GE48: 404.6 | GF48: 376 | GG48: 390.6 | GH48: 398 | GI48: 376 | GJ48: 387 | GW48: 310 | GX48: 300 | GY48: 305
A49: 1990 | B49: 4 | C49: 12 | D49: 182.25 | E49: 179 | F49: 181 | G49: 150.25 | H49: 148 | I49: 149.25 | J49: 159.5 | K49: 158 | L49: 159 | P49: 178 | Q49: 174.25 | R49: 176.5 | S49: 178 | T49: 174.25 | U49: 176.5 | AZ49: 212 | BA49: 208.66667 | BB49: 210.33333 | BF49: 212 | BG49: 208.66667 | BH49: 210.33333 | BI49: 200 | BJ49: 198 | BK49: 199 | CP49: 225.66667 | CQ49: 220.66667 | CR49: 223.66667 | CS49: 230 | CT49: 210 | CU49: 220 | CV49: 205 | CW49: 190 | CX49: 198 | DT49: 169 | DU49: 163 | DV49: 166 | FJ49: 163 | FK49: 159.33333 | FL49: 161.66667 | FP49: 132.75 | FQ49: 128.75 | FR49: 131 | FS49: 153.66667 | FT49: 149 | FU49: 151.66667 | GB49: 321.66667 | GC49: 305 | GD49: 313.66667 | GE49: 401.66667 | GF49: 376 | GG49: 389.33333 | GH49: 390 | GI49: 376 | GJ49: 383 | GW49: 310 | GX49: 300 | GY49: 305
A50: 1991 | B50: 1 | C50: 1 | D50: 180 | E50: 175.5 | F50: 178 | G50: 148 | H50: 146.25 | I50: 147.5 | J50: 158 | K50: 156.5 | L50: 157.75 | P50: 178 | Q50: 173 | R50: 176 | S50: 178 | T50: 173 | U50: 176 | AZ50: 211 | BA50: 208.4 | BB50: 210 | BF50: 211 | BG50: 208.4 | BH50: 210 | BI50: 200 | BJ50: 197.8 | BK50: 199 | CP50: 225 | CQ50: 221.8 | CR50: 223.6 | CS50: 230 | CT50: 210 | CU50: 220 | CV50: 205 | CW50: 190 | CX50: 198 | DT50: 169 | DU50: 163 | DV50: 166 | FJ50: 163 | FK50: 157.8 | FL50: 160.6 | FP50: 127 | FQ50: 122.66667 | FR50: 125.33333 | FS50: 155 | FT50: 150 | FU50: 153 | GB50: 310 | GC50: 305 | GD50: 308 | GE50: 395 | GF50: 391.2 | GG50: 393.2 | GH50: 366 | GI50: 355.2 | GJ50: 360.6 | GW50: 290 | GX50: 280 | GY50: 285
A51: 1991 | B51: 1 | C51: 2 | D51: 184.75 | E51: 182.75 | F51: 183.75 | G51: 151.5 | H51: 148.75 | I51: 150.25 | J51: 163.5 | K51: 159.75 | L51: 161.75 | P51: 177 | Q51: 172 | R51: 175 | S51: 177 | T51: 172 | U51: 175 | AZ51: 211.75 | BA51: 207.5 | BB51: 210 | BF51: 211.75 | BG51: 207.5 | BH51: 210 | BI51: 210 | BJ51: 200 | BK51: 205 | CP51: 225 | CQ51: 222.25 | CR51: 223.75 | CS51: 230 | CT51: 210 | CU51: 220 | CV51: 205 | CW51: 190 | CX51: 198 | DT51: 169 | DU51: 163 | DV51: 166 | FJ51: 160 | FK51: 157 | FL51: 159 | FP51: 126 | FQ51: 121 | FR51: 123.5 | FS51: 155 | FT51: 150 | FU51: 153 | GB51: 330 | GC51: 311 | GD51: 320.5 | GE51: 395 | GF51: 395 | GG51: 395 | GH51: 360 | GI51: 350 | GJ51: 355 | GW51: 288 | GX51: 277.5 | GY51: 282.75
A52: 1991 | B52: 1 | C52: 3 | D52: 183.25 | E52: 181.5 | F52: 182.5 | G52: 153.25 | H52: 149.5 | I52: 151.5 | J52: 164.5 | K52: 162.75 | L52: 163.75 | P52: 177.25 | Q52: 172.75 | R52: 175.5 | S52: 176.5 | T52: 169.5 | U52: 173.5 | AZ52: 208 | BA52: 206 | BB52: 207 | BF52: 208 | BG52: 206 | BH52: 207 | BI52: 210 | BJ52: 202.5 | BK52: 206.5 | CP52: 230.25 | CQ52: 226.5 | CR52: 228.75 | CS52: 230 | CT52: 210 | CU52: 220 | CV52: 202.5 | CW52: 190 | CX52: 196.5 | DT52: 169 | DU52: 163 | DV52: 166 | FJ52: 161 | FK52: 157 | FL52: 159.5 | FP52: 126.5 | FQ52: 124.5 | FR52: 125.5 | FS52: 150 | FT52: 145 | FU52: 148 | GB52: 327.5 | GC52: 310.25 | GD52: 319 | GE52: 398.75 | GF52: 398 | GG52: 398.75 | GH52: 360 | GI52: 350 | GJ52: 355 | GW52: 287 | GX52: 275 | GY52: 281
A53: 1991 | B53: 2 | C53: 4 | D53: 180 | E53: 177 | F53: 178.75 | G53: 153.5 | H53: 149.25 | I53: 151.5 | J53: 166.75 | K53: 165.5 | L53: 166.5 | P53: 180 | Q53: 175 | R53: 178 | S53: 179 | T53: 174.5 | U53: 177.25 | AZ53: 208 | BA53: 206 | BB53: 207 | BF53: 208 | BG53: 206 | BH53: 207 | BI53: 210 | BJ53: 201.25 | BK53: 205.75 | CP53: 226.25 | CQ53: 223 | CR53: 225 | CS53: 225 | CT53: 210 | CU53: 218 | CV53: 195 | CW53: 187.5 | CX53: 191.5 | DT53: 169 | DU53: 163 | DV53: 166 | FJ53: 161 | FK53: 157.5 | FL53: 159.5 | FP53: 126 | FQ53: 123.25 | FR53: 125 | FS53: 144.75 | FT53: 140.75 | FU53: 143.25 | GB53: 325 | GC53: 309 | GD53: 317 | GE53: 400 | GF53: 399 | GG53: 400 | GH53: 361.25 | GI53: 351.25 | GJ53: 356.25 | GW53: 287 | GX53: 275 | GY53: 281
A54: 1991 | B54: 2 | C54: 5 | D54: 177.6 | E54: 175 | F54: 176.6 | G54: 153.2 | H54: 151 | I54: 152.2 | J54: 166.4 | K54: 164.6 | L54: 165.4 | P54: 179.2 | Q54: 175 | R54: 177.6 | S54: 179.2 | T54: 175 | U54: 177.6 | AZ54: 208 | BA54: 205.25 | BB54: 207 | BF54: 208 | BG54: 205.25 | BH54: 207 | BI54: 210 | BJ54: 200 | BK54: 205 | CP54: 218.75 | CQ54: 216.25 | CR54: 218 | CS54: 225 | CT54: 210 | CU54: 218 | CV54: 193 | CW54: 185 | CX54: 189.2 | DT54: 169 | DU54: 163 | DV54: 166 | FJ54: 149.5 | FK54: 146.75 | FL54: 148.25 | FP54: 125 | FQ54: 121.6 | FR54: 123.8 | FS54: 132.5 | FT54: 129.25 | FU54: 131.25 | GB54: 325 | GC54: 309 | GD54: 317 | GE54: 400 | GF54: 399 | GG54: 400 | GH54: 360 | GI54: 350 | GJ54: 355 | GW54: 287 | GX54: 276.25 | GY54: 281.75
A55: 1991 | B55: 2 | C55: 6 | D55: 178.5 | E55: 176.5 | F55: 177.5 | G55: 152 | H55: 148.5 | I55: 150.25 | J55: 159 | K55: 157.5 | L55: 158.75 | P55: 176.5 | Q55: 172.5 | R55: 175 | S55: 176.5 | T55: 172.5 | U55: 175 | AZ55: 200.75 | BA55: 195.25 | BB55: 198.5 | BF55: 200.75 | BG55: 195.25 | BH55: 198.5 | BI55: 202.5 | BJ55: 199 | BK55: 201 | CP55: 214.5 | CQ55: 211.5 | CR55: 213.25 | CS55: 225 | CT55: 210 | CU55: 218 | CV55: 195 | CW55: 185 | CX55: 190 | DT55: 169 | DU55: 163 | DV55: 166 | FJ55: 143.5 | FK55: 140 | FL55: 142.25 | FP55: 122 | FQ55: 119.25 | FR55: 121 | FS55: 130 | FT55: 129 | FU55: 130 | GB55: 325 | GC55: 309 | GD55: 317 | GE55: 400 | GF55: 399 | GG55: 400 | GH55: 360 | GI55: 350 | GJ55: 355 | GW55: 285.5 | GX55: 276.25 | GY55: 281
A56: 1991 | B56: 3 | C56: 7 | D56: 185 | E56: 182.75 | F56: 184 | G56: 153.25 | H56: 151.25 | I56: 152.25 | J56: 164 | K56: 162.75 | L56: 163.75 | P56: 178.25 | Q56: 175 | R56: 177 | S56: 178.25 | T56: 175 | U56: 177 | AZ56: 201.25 | BA56: 194 | BB56: 198 | BF56: 201.25 | BG56: 194 | BH56: 198 | BI56: 202.5 | BJ56: 199 | BK56: 201 | CP56: 215 | CQ56: 212 | CR56: 214 | CS56: 225 | CT56: 210 | CU56: 218 | CV56: 202.5 | CW56: 185 | CX56: 193.75 | DT56: 169 | DU56: 163 | DV56: 166 | FJ56: 143 | FK56: 138 | FL56: 141 | FP56: 122.5 | FQ56: 119.5 | FR56: 121.5 | FS56: 132 | FT56: 130 | FU56: 131 | GB56: 322.5 | GC56: 309 | GD56: 316 | GE56: 410 | GF56: 409 | GG56: 410 | GH56: 360 | GI56: 350 | GJ56: 355 | GW56: 285 | GX56: 280 | GY56: 283
