Workbook
Name \a: #REF!
Name \d: #REF!
Name \I: #REF!
Name \p: #REF!
Name \s: #REF!
Name \t: #REF!
Name _1_: #REF!
Name _10n_0: #REF!
Name _11t_0WT: #REF!
Name _12t__WT: #REF!
Name _13W_0WS: #REF!
Name _14WSOL: #REF!
Name _15W__WS: #REF!
Name _2_0: #REF!
Name _3_0G: #REF!
Name _4_0WSOL: #REF!
Name _5_1thru51queries: #REF!
Name _6_8_0WTOT: #REF!
Name _7_8__WTOT: #REF!
Name _8G: #REF!
Name _9n: #REF!
Name aagr1end: #REF!
Name aagr1start: #REF!
Name aagr2end: #REF!
Name aagr2start: #REF!
Name aagr3end: #REF!
Name aagr3start: #REF!
Name aagr4end: #REF!
Name aagr4start: #REF!
Name aagr5end: #REF!
Name aagr5start: #REF!
Name ALL: #REF!
Name AllApps: #REF!
Name annual: #REF!
Name Applications: #REF!
Name area: #REF!
Name ASD: #REF!
Name ASPHTON: #REF!
Name AVGASTON: #REF!
Name AvgCflow: #REF!
Name b: #REF!
Name Base_Year: #REF!
Name Bitumen: #REF!
Name Break: #REF!
Name Canada_East_Projects: #REF!
Name Canada_West_Projects: #REF!
Name CapOpCost: #REF!
Name CapOpCostHi: #REF!
Name Chosen_month: #REF!
Name Chosen_quarter: #REF!
Name Chosen_year: #REF!
Name clean_spreads: #REF!
Name COKETON: #REF!
Name CommercialExAIGMetrics: #REF!
Name CONSTANT1: #N/A
Name CONSTANT2: #N/A
Name CostEsc: #REF!
Name Country: #REF!
Name CRUTON: #REF!
Name CURRENT1: #REF!

Sheet Simulateur sur Avg
AA1: ConvCost=20+0,05×(SFOBME​+Fret)
J2: used for ACS production cost estimation
E3: Sulphuric Acid Bulk FOB | F3: Sulphuric Acid Bulk FOB | G3: Sulphuric Acid Bulk FOB | H3: Sulphuric Acid Bulk CFR | I3: Sulphur Bulk FOB | J3: Sulphur Bulk CFR | L3: Sulphuric Acid Bulk FOB | M3: Sulphuric Acid Bulk FOB | N3: Sulphuric Acid Bulk FOB | O3: Sulphur Bulk FOB | P3: Sulphur Bulk CFR
E4: Japan/South Korea Spot | F4: NW Europe 30 days Spot | G4: China Spot | H4: North Africa, Spot | I4: Middle East Spot | J4: North Africa | L4: Japan/South Korea Spot | M4: NW Europe 30 days Spot | N4: China Spot | O4: Middle East Spot | P4: North Africa | R4: Prix cibles Sulphuric Acid | AA4: Formule 1: Market Basket | AD4: Formule 2: Indice Composite basé sur Europe, chine et acid base ME
B5: Year | C5: Quarter | D5: Month | E5: ACS FOB Japan | F5: ACS FOB NW Europe | G5: ACS FOB China Spot | H5: ACS CFR North Africa Spot | I5: Sulphur Bulk FOB Middle East | J5: Sulphur Bulk CFR North Africa | L5: Fret Japan to Morocco | M5: Fret NW EU to Morocco | N5: Fret China to Morocco | O5: Fret Middle East to Morocco | P5: Freight adjustment (CRU) | R5: ACS CFR North Africa | S5: IPP ACS Origine Europe | T5: IPP ACS origine Japon | U5: Ipp ACS Origine Chine | V5: Sulfur ME to CFR Morocco | W5: Sulfur North Africa to CFR Morocco | X5: ACS S based from Sulfur ME | Y5: ACS S based from Sulfur North Africa | AA5: IPP_Acid = 40% × IPP_NWE + 30% × IPP_Japan + 30% × IPP_China | AB5: Gain par rapport à production sur place | AD5: IPP_Acid = min((70% × IPP_NWE + 30% × IPP_China); Acid S Based ME) | AE5: Gain par rapport à production sur place
B6: 2002 | C6: 2 | D6: 5 | E6: ='CRU historical'!F5 | F6: ='CRU historical'!I5 -> 6 | G6: ='CRU historical'!L5 | H6: ='CRU historical'!O5 | I6: ='CRU historical'!R5 | J6: =AVERAGE('CRU historical'!U5, 'CRU historical'!X5, 'CRU historical'!AA5, 'CRU historical'!AD5) -> 33 | L6: {=IFERROR(SUMPRODUCT(('Sulphuric Acid freights'!$B$3:$B$513=B6)*('Sulphuric Acid freights'!$D$3:$D$513=D6)*('Sulphuric Acid freights'!$P$3:$P$513))/SUMPRODUCT(('Sulphuric Acid freights'!$B$3:$B$513=B6)*('Sulphuric Acid freights'!$D$3:$D$513=D6)*1), AVERAGE('Sulphuric Acid freights'!$P$3:$P$513))*2/3} -> 54.110672 | M6: {=IFERROR(SUMPRODUCT(('Sulphuric Acid freights'!$B$3:$B$513=B6)*('Sulphuric Acid freights'!$D$3:$D$513=D6)*('Sulphuric Acid freights'!$M$3:$M$513))/SUMPRODUCT(('Sulphuric Acid freights'!$B$3:$B$513=B6)*('Sulphuric Acid freights'!$D$3:$D$513=D6)*1)*2/3, AVERAGE('Sulphuric Acid freights'!$M$3:$M$513))} -> 23.573123 | N6: =IFERROR(L6*0.9, "") -> 48.699605 | O6: {=IF(SUMPRODUCT(('Sulphur freight'!$B$3:$B$1976=B6)*('Sulphur freight'!$D$3:$D$1976=D6)*('Sulphur freight'!$G$3:$G$1976))/SUMPRODUCT(('Sulphur freight'!$B$3:$B$1976=B6)*('Sulphur freight'!$D$3:$D$1976=D6)*1)=0, AVERAGE('Sulphur freight'!$G$3:$G$1976),SUMPRODUCT(('Sulphur freight'!$B$3:$B$1976=B6)*('Sulphur freight'!$D$3:$D$1976=D6)*('Sulphur freight'!$G$3:$G$1976))/SUMPRODUCT(('Sulphur freight'!$B$3:$B$1976=B6)*('Sulphur freight'!$D$3:$D$1976=D6)*1))} -> 29.165429 | P6: 20 | R6: =H6 | S6: =IF(F6=0, "", F6+M6) -> 29.573123 | T6: =IFERROR( E6+L6, "") | U6: =IFERROR( G6+N6, "") | V6: =IFERROR(I6+O6, "") | W6: =J6+P6 -> 53 | X6: =IFERROR((I6+O6)*0.33+18, "") | Y6: =IF(J6=0,0,(J6+P6)*0.33+18) -> 35.49 | AA6: =IF(OR(S6="", T6="", U6=""), "", MAX(R6,S6)*40%+T6*30%+U6*30%) | AB6: =IF(AA6="", "", MAX(X6, Y6)-AA6) | AD6: =IFERROR(MIN((MAX(R6,S6)*70%+U6*30%), Y6), "") | AE6: =IF(AD6="", "", MAX(AA6, AB6)-AD6)
B7: 2002 | C7: 2 | D7: 6 | E7: ='CRU historical'!F6 | F7: ='CRU historical'!I6 -> 6 | G7: ='CRU historical'!L6 | H7: ='CRU historical'!O6 | I7: ='CRU historical'!R6 | J7: =AVERAGE('CRU historical'!U6, 'CRU historical'!X6, 'CRU historical'!AA6, 'CRU historical'!AD6) -> 33 | L7: {=IFERROR(SUMPRODUCT(('Sulphuric Acid freights'!$B$3:$B$513=B7)*('Sulphuric Acid freights'!$D$3:$D$513=D7)*('Sulphuric Acid freights'!$P$3:$P$513))/SUMPRODUCT(('Sulphuric Acid freights'!$B$3:$B$513=B7)*('Sulphuric Acid freights'!$D$3:$D$513=D7)*1), AVERAGE('Sulphuric Acid freights'!$P$3:$P$513))*2/3} -> 54.110672 | M7: {=IFERROR(SUMPRODUCT(('Sulphuric Acid freights'!$B$3:$B$513=B7)*('Sulphuric Acid freights'!$D$3:$D$513=D7)*('Sulphuric Acid freights'!$M$3:$M$513))/SUMPRODUCT(('Sulphuric Acid freights'!$B$3:$B$513=B7)*('Sulphuric Acid freights'!$D$3:$D$513=D7)*1)*2/3, AVERAGE('Sulphuric Acid freights'!$M$3:$M$513))} -> 23.573123 | N7: =IFERROR(L7*0.9, "") -> 48.699605 | O7: {=IF(SUMPRODUCT(('Sulphur freight'!$B$3:$B$1976=B7)*('Sulphur freight'!$D$3:$D$1976=D7)*('Sulphur freight'!$G$3:$G$1976))/SUMPRODUCT(('Sulphur freight'!$B$3:$B$1976=B7)*('Sulphur freight'!$D$3:$D$1976=D7)*1)=0, AVERAGE('Sulphur freight'!$G$3:$G$1976),SUMPRODUCT(('Sulphur freight'!$B$3:$B$1976=B7)*('Sulphur freight'!$D$3:$D$1976=D7)*('Sulphur freight'!$G$3:$G$1976))/SUMPRODUCT(('Sulphur freight'!$B$3:$B$1976=B7)*('Sulphur freight'!$D$3:$D$1976=D7)*1))} -> 29.165429 | P7: 20 | R7: =H7 | S7: =IF(F7=0, "", F7+M7) -> 29.573123 | T7: =IFERROR( E7+L7, "") | U7: =IFERROR( G7+N7, "") | V7: =IFERROR(I7+O7, "") | W7: =J7+P7 -> 53 | X7: =IFERROR((I7+O7)*0.33+18, "") | Y7: =IF(J7=0,0,(J7+P7)*0.33+18) -> 35.49 | AA7: =IF(OR(S7="", T7="", U7=""), "", MAX(R7,S7)*40%+T7*30%+U7*30%) | AB7: =IF(AA7="", "", MAX(X7, Y7)-AA7) | AD7: =IFERROR(MIN((MAX(R7,S7)*70%+U7*30%), Y7), "") | AE7: =IF(AD7="", "", MAX(AA7, AB7)-AD7)
B8: 2002 | C8: 3 | D8: 7 | E8: ='CRU historical'!F7 | F8: ='CRU historical'!I7 -> 8 | G8: ='CRU historical'!L7 | H8: ='CRU historical'!O7 | I8: ='CRU historical'!R7 | J8: =AVERAGE('CRU historical'!U7, 'CRU historical'!X7, 'CRU historical'!AA7, 'CRU historical'!AD7) -> 39 | L8: {=IFERROR(SUMPRODUCT(('Sulphuric Acid freights'!$B$3:$B$513=B8)*('Sulphuric Acid freights'!$D$3:$D$513=D8)*('Sulphuric Acid freights'!$P$3:$P$513))/SUMPRODUCT(('Sulphuric Acid freights'!$B$3:$B$513=B8)*('Sulphuric Acid freights'!$D$3:$D$513=D8)*1), AVERAGE('Sulphuric Acid freights'!$P$3:$P$513))*2/3} -> 54.110672 | M8: {=IFERROR(SUMPRODUCT(('Sulphuric Acid freights'!$B$3:$B$513=B8)*('Sulphuric Acid freights'!$D$3:$D$513=D8)*('Sulphuric Acid freights'!$M$3:$M$513))/SUMPRODUCT(('Sulphuric Acid freights'!$B$3:$B$513=B8)*('Sulphuric Acid freights'!$D$3:$D$513=D8)*1)*2/3, AVERAGE('Sulphuric Acid freights'!$M$3:$M$513))} -> 23.573123 | N8: =IFERROR(L8*0.9, "") -> 48.699605 | O8: {=IF(SUMPRODUCT(('Sulphur freight'!$B$3:$B$1976=B8)*('Sulphur freight'!$D$3:$D$1976=D8)*('Sulphur freight'!$G$3:$G$1976))/SUMPRODUCT(('Sulphur freight'!$B$3:$B$1976=B8)*('Sulphur freight'!$D$3:$D$1976=D8)*1)=0, AVERAGE('Sulphur freight'!$G$3:$G$1976),SUMPRODUCT(('Sulphur freight'!$B$3:$B$1976=B8)*('Sulphur freight'!$D$3:$D$1976=D8)*('Sulphur freight'!$G$3:$G$1976))/SUMPRODUCT(('Sulphur freight'!$B$3:$B$1976=B8)*('Sulphur freight'!$D$3:$D$1976=D8)*1))} -> 29.165429 | P8: 20 | R8: =H8 | S8: =IF(F8=0, "", F8+M8) -> 31.573123 | T8: =IFERROR( E8+L8, "") | U8: =IFERROR( G8+N8, "") | V8: =IFERROR(I8+O8, "") | W8: =J8+P8 -> 59 | X8: =IFERROR((I8+O8)*0.33+18, "") | Y8: =IF(J8=0,0,(J8+P8)*0.33+18) -> 37.47 | AA8: =IF(OR(S8="", T8="", U8=""), "", MAX(R8,S8)*40%+T8*30%+U8*30%) | AB8: =IF(AA8="", "", MAX(X8, Y8)-AA8) | AD8: =IFERROR(MIN((MAX(R8,S8)*70%+U8*30%), Y8), "") | AE8: =IF(AD8="", "", MAX(AA8, AB8)-AD8)
B9: 2002 | C9: 3 | D9: 8 | E9: ='CRU historical'!F8 | F9: ='CRU historical'!I8 -> 8 | G9: ='CRU historical'!L8 | H9: ='CRU historical'!O8 | I9: ='CRU historical'!R8 | J9: =AVERAGE('CRU historical'!U8, 'CRU historical'!X8, 'CRU historical'!AA8, 'CRU historical'!AD8) -> 38.5 | L9: {=IFERROR(SUMPRODUCT(('Sulphuric Acid freights'!$B$3:$B$513=B9)*('Sulphuric Acid freights'!$D$3:$D$513=D9)*('Sulphuric Acid freights'!$P$3:$P$513))/SUMPRODUCT(('Sulphuric Acid freights'!$B$3:$B$513=B9)*('Sulphuric Acid freights'!$D$3:$D$513=D9)*1), AVERAGE('Sulphuric Acid freights'!$P$3:$P$513))*2/3} -> 54.110672 | M9: {=IFERROR(SUMPRODUCT(('Sulphuric Acid freights'!$B$3:$B$513=B9)*('Sulphuric Acid freights'!$D$3:$D$513=D9)*('Sulphuric Acid freights'!$M$3:$M$513))/SUMPRODUCT(('Sulphuric Acid freights'!$B$3:$B$513=B9)*('Sulphuric Acid freights'!$D$3:$D$513=D9)*1)*2/3, AVERAGE('Sulphuric Acid freights'!$M$3:$M$513))} -> 23.573123 | N9: =IFERROR(L9*0.9, "") -> 48.699605 | O9: {=IF(SUMPRODUCT(('Sulphur freight'!$B$3:$B$1976=B9)*('Sulphur freight'!$D$3:$D$1976=D9)*('Sulphur freight'!$G$3:$G$1976))/SUMPRODUCT(('Sulphur freight'!$B$3:$B$1976=B9)*('Sulphur freight'!$D$3:$D$1976=D9)*1)=0, AVERAGE('Sulphur freight'!$G$3:$G$1976),SUMPRODUCT(('Sulphur freight'!$B$3:$B$1976=B9)*('Sulphur freight'!$D$3:$D$1976=D9)*('Sulphur freight'!$G$3:$G$1976))/SUMPRODUCT(('Sulphur freight'!$B$3:$B$1976=B9)*('Sulphur freight'!$D$3:$D$1976=D9)*1))} -> 29.165429 | P9: 20 | R9: =H9 | S9: =IF(F9=0, "", F9+M9) -> 31.573123 | T9: =IFERROR( E9+L9, "") | U9: =IFERROR( G9+N9, "") | V9: =IFERROR(I9+O9, "") | W9: =J9+P9 -> 58.5 | X9: =IFERROR((I9+O9)*0.33+18, "") | Y9: =IF(J9=0,0,(J9+P9)*0.33+18) -> 37.305 | AA9: =IF(OR(S9="", T9="", U9=""), "", MAX(R9,S9)*40%+T9*30%+U9*30%) | AB9: =IF(AA9="", "", MAX(X9, Y9)-AA9) | AD9: =IFERROR(MIN((MAX(R9,S9)*70%+U9*30%), Y9), "") | AE9: =IF(AD9="", "", MAX(AA9, AB9)-AD9)
B10: 2002 | C10: 3 | D10: 9 | E10: ='CRU historical'!F9 | F10: ='CRU historical'!I9 -> 8 | G10: ='CRU historical'!L9 | H10: ='CRU historical'!O9 | I10: ='CRU historical'!R9 | J10: =AVERAGE('CRU historical'!U9, 'CRU historical'!X9, 'CRU historical'!AA9, 'CRU historical'!AD9) -> 38 | L10: {=IFERROR(SUMPRODUCT(('Sulphuric Acid freights'!$B$3:$B$513=B10)*('Sulphuric Acid freights'!$D$3:$D$513=D10)*('Sulphuric Acid freights'!$P$3:$P$513))/SUMPRODUCT(('Sulphuric Acid freights'!$B$3:$B$513=B10)*('Sulphuric Acid freights'!$D$3:$D$513=D10)*1), AVERAGE('Sulphuric Acid freights'!$P$3:$P$513))*2/3} -> 54.110672 | M10: {=IFERROR(SUMPRODUCT(('Sulphuric Acid freights'!$B$3:$B$513=B10)*('Sulphuric Acid freights'!$D$3:$D$513=D10)*('Sulphuric Acid freights'!$M$3:$M$513))/SUMPRODUCT(('Sulphuric Acid freights'!$B$3:$B$513=B10)*('Sulphuric Acid freights'!$D$3:$D$513=D10)*1)*2/3, AVERAGE('Sulphuric Acid freights'!$M$3:$M$513))} -> 23.573123 | N10: =IFERROR(L10*0.9, "") -> 48.699605 | O10: {=IF(SUMPRODUCT(('Sulphur freight'!$B$3:$B$1976=B10)*('Sulphur freight'!$D$3:$D$1976=D10)*('Sulphur freight'!$G$3:$G$1976))/SUMPRODUCT(('Sulphur freight'!$B$3:$B$1976=B10)*('Sulphur freight'!$D$3:$D$1976=D10)*1)=0, AVERAGE('Sulphur freight'!$G$3:$G$1976),SUMPRODUCT(('Sulphur freight'!$B$3:$B$1976=B10)*('Sulphur freight'!$D$3:$D$1976=D10)*('Sulphur freight'!$G$3:$G$1976))/SUMPRODUCT(('Sulphur freight'!$B$3:$B$1976=B10)*('Sulphur freight'!$D$3:$D$1976=D10)*1))} -> 29.165429 | P10: 20 | R10: =H10 | S10: =IF(F10=0, "", F10+M10) -> 31.573123 | T10: =IFERROR( E10+L10, "") | U10: =IFERROR( G10+N10, "") | V10: =IFERROR(I10+O10, "") | W10: =J10+P10 -> 58 | X10: =IFERROR((I10+O10)*0.33+18, "") | Y10: =IF(J10=0,0,(J10+P10)*0.33+18) -> 37.14 | AA10: =IF(OR(S10="", T10="", U10=""), "", MAX(R10,S10)*40%+T10*30%+U10*30%) | AB10: =IF(AA10="", "", MAX(X10, Y10)-AA10) | AD10: =IFERROR(MIN((MAX(R10,S10)*70%+U10*30%), Y10), "") | AE10: =IF(AD10="", "", MAX(AA10, AB10)-AD10)
B11: 2002 | C11: 4 | D11: 10 | E11: ='CRU historical'!F10 | F11: ='CRU historical'!I10 -> 8 | G11: ='CRU historical'!L10 | H11: ='CRU historical'!O10 | I11: ='CRU historical'!R10 | J11: =AVERAGE('CRU historical'!U10, 'CRU historical'!X10, 'CRU historical'!AA10, 'CRU historical'!AD10) -> 38 | L11: {=IFERROR(SUMPRODUCT(('Sulphuric Acid freights'!$B$3:$B$513=B11)*('Sulphuric Acid freights'!$D$3:$D$513=D11)*('Sulphuric Acid freights'!$P$3:$P$513))/SUMPRODUCT(('Sulphuric Acid freights'!$B$3:$B$513=B11)*('Sulphuric Acid freights'!$D$3:$D$513=D11)*1), AVERAGE('Sulphuric Acid freights'!$P$3:$P$513))*2/3} -> 54.110672 | M11: {=IFERROR(SUMPRODUCT(('Sulphuric Acid freights'!$B$3:$B$513=B11)*('Sulphuric Acid freights'!$D$3:$D$513=D11)*('Sulphuric Acid freights'!$M$3:$M$513))/SUMPRODUCT(('Sulphuric Acid freights'!$B$3:$B$513=B11)*('Sulphuric Acid freights'!$D$3:$D$513=D11)*1)*2/3, AVERAGE('Sulphuric Acid freights'!$M$3:$M$513))} -> 23.573123 | N11: =IFERROR(L11*0.9, "") -> 48.699605 | O11: {=IF(SUMPRODUCT(('Sulphur freight'!$B$3:$B$1976=B11)*('Sulphur freight'!$D$3:$D$1976=D11)*('Sulphur freight'!$G$3:$G$1976))/SUMPRODUCT(('Sulphur freight'!$B$3:$B$1976=B11)*('Sulphur freight'!$D$3:$D$1976=D11)*1)=0, AVERAGE('Sulphur freight'!$G$3:$G$1976),SUMPRODUCT(('Sulphur freight'!$B$3:$B$1976=B11)*('Sulphur freight'!$D$3:$D$1976=D11)*('Sulphur freight'!$G$3:$G$1976))/SUMPRODUCT(('Sulphur freight'!$B$3:$B$1976=B11)*('Sulphur freight'!$D$3:$D$1976=D11)*1))} -> 29.165429 | P11: 20 | R11: =H11 | S11: =IF(F11=0, "", F11+M11) -> 31.573123 | T11: =IFERROR( E11+L11, "") | U11: =IFERROR( G11+N11, "") | V11: =IFERROR(I11+O11, "") | W11: =J11+P11 -> 58 | X11: =IFERROR((I11+O11)*0.33+18, "") | Y11: =IF(J11=0,0,(J11+P11)*0.33+18) -> 37.14 | AA11: =IF(OR(S11="", T11="", U11=""), "", MAX(R11,S11)*40%+T11*30%+U11*30%) | AB11: =IF(AA11="", "", MAX(X11, Y11)-AA11) | AD11: =IFERROR(MIN((MAX(R11,S11)*70%+U11*30%), Y11), "") | AE11: =IF(AD11="", "", MAX(AA11, AB11)-AD11)
B12: 2002 | C12: 4 | D12: 11 | E12: ='CRU historical'!F11 | F12: ='CRU historical'!I11 -> 11 | G12: ='CRU historical'!L11 | H12: ='CRU historical'!O11 | I12: ='CRU historical'!R11 | J12: =AVERAGE('CRU historical'!U11, 'CRU historical'!X11, 'CRU historical'!AA11, 'CRU historical'!AD11) -> 39 | L12: {=IFERROR(SUMPRODUCT(('Sulphuric Acid freights'!$B$3:$B$513=B12)*('Sulphuric Acid freights'!$D$3:$D$513=D12)*('Sulphuric Acid freights'!$P$3:$P$513))/SUMPRODUCT(('Sulphuric Acid freights'!$B$3:$B$513=B12)*('Sulphuric Acid freights'!$D$3:$D$513=D12)*1), AVERAGE('Sulphuric Acid freights'!$P$3:$P$513))*2/3} -> 54.110672 | M12: {=IFERROR(SUMPRODUCT(('Sulphuric Acid freights'!$B$3:$B$513=B12)*('Sulphuric Acid freights'!$D$3:$D$513=D12)*('Sulphuric Acid freights'!$M$3:$M$513))/SUMPRODUCT(('Sulphuric Acid freights'!$B$3:$B$513=B12)*('Sulphuric Acid freights'!$D$3:$D$513=D12)*1)*2/3, AVERAGE('Sulphuric Acid freights'!$M$3:$M$513))} -> 23.573123 | N12: =IFERROR(L12*0.9, "") -> 48.699605 | O12: {=IF(SUMPRODUCT(('Sulphur freight'!$B$3:$B$1976=B12)*('Sulphur freight'!$D$3:$D$1976=D12)*('Sulphur freight'!$G$3:$G$1976))/SUMPRODUCT(('Sulphur freight'!$B$3:$B$1976=B12)*('Sulphur freight'!$D$3:$D$1976=D12)*1)=0, AVERAGE('Sulphur freight'!$G$3:$G$1976),SUMPRODUCT(('Sulphur freight'!$B$3:$B$1976=B12)*('Sulphur freight'!$D$3:$D$1976=D12)*('Sulphur freight'!$G$3:$G$1976))/SUMPRODUCT(('Sulphur freight'!$B$3:$B$1976=B12)*('Sulphur freight'!$D$3:$D$1976=D12)*1))} -> 29.165429 | P12: 20 | R12: =H12 | S12: =IF(F12=0, "", F12+M12) -> 34.573123 | T12: =IFERROR( E12+L12, "") | U12: =IFERROR( G12+N12, "") | V12: =IFERROR(I12+O12, "") | W12: =J12+P12 -> 59 | X12: =IFERROR((I12+O12)*0.33+18, "") | Y12: =IF(J12=0,0,(J12+P12)*0.33+18) -> 37.47 | AA12: =IF(OR(S12="", T12="", U12=""), "", MAX(R12,S12)*40%+T12*30%+U12*30%) | AB12: =IF(AA12="", "", MAX(X12, Y12)-AA12) | AD12: =IFERROR(MIN((MAX(R12,S12)*70%+U12*30%), Y12), "") | AE12: =IF(AD12="", "", MAX(AA12, AB12)-AD12)
B13: 2002 | C13: 4 | D13: 12 | E13: ='CRU historical'!F12 | F13: ='CRU historical'!I12 -> 11 | G13: ='CRU historical'!L12 | H13: ='CRU historical'!O12 | I13: ='CRU historical'!R12 | J13: =AVERAGE('CRU historical'!U12, 'CRU historical'!X12, 'CRU historical'!AA12, 'CRU historical'!AD12) -> 39 | L13: {=IFERROR(SUMPRODUCT(('Sulphuric Acid freights'!$B$3:$B$513=B13)*('Sulphuric Acid freights'!$D$3:$D$513=D13)*('Sulphuric Acid freights'!$P$3:$P$513))/SUMPRODUCT(('Sulphuric Acid freights'!$B$3:$B$513=B13)*('Sulphuric Acid freights'!$D$3:$D$513=D13)*1), AVERAGE('Sulphuric Acid freights'!$P$3:$P$513))*2/3} -> 54.110672 | M13: {=IFERROR(SUMPRODUCT(('Sulphuric Acid freights'!$B$3:$B$513=B13)*('Sulphuric Acid freights'!$D$3:$D$513=D13)*('Sulphuric Acid freights'!$M$3:$M$513))/SUMPRODUCT(('Sulphuric Acid freights'!$B$3:$B$513=B13)*('Sulphuric Acid freights'!$D$3:$D$513=D13)*1)*2/3, AVERAGE('Sulphuric Acid freights'!$M$3:$M$513))} -> 23.573123 | N13: =IFERROR(L13*0.9, "") -> 48.699605 | O13: {=IF(SUMPRODUCT(('Sulphur freight'!$B$3:$B$1976=B13)*('Sulphur freight'!$D$3:$D$1976=D13)*('Sulphur freight'!$G$3:$G$1976))/SUMPRODUCT(('Sulphur freight'!$B$3:$B$1976=B13)*('Sulphur freight'!$D$3:$D$1976=D13)*1)=0, AVERAGE('Sulphur freight'!$G$3:$G$1976),SUMPRODUCT(('Sulphur freight'!$B$3:$B$1976=B13)*('Sulphur freight'!$D$3:$D$1976=D13)*('Sulphur freight'!$G$3:$G$1976))/SUMPRODUCT(('Sulphur freight'!$B$3:$B$1976=B13)*('Sulphur freight'!$D$3:$D$1976=D13)*1))} -> 29.165429 | P13: 20 | R13: =H13 | S13: =IF(F13=0, "", F13+M13) -> 34.573123 | T13: =IFERROR( E13+L13, "") | U13: =IFERROR( G13+N13, "") | V13: =IFERROR(I13+O13, "") | W13: =J13+P13 -> 59 | X13: =IFERROR((I13+O13)*0.33+18, "") | Y13: =IF(J13=0,0,(J13+P13)*0.33+18) -> 37.47 | AA13: =IF(OR(S13="", T13="", U13=""), "", MAX(R13,S13)*40%+T13*30%+U13*30%) | AB13: =IF(AA13="", "", MAX(X13, Y13)-AA13) | AD13: =IFERROR(MIN((MAX(R13,S13)*70%+U13*30%), Y13), "") | AE13: =IF(AD13="", "", MAX(AA13, AB13)-AD13)
B14: 2003 | C14: 1 | D14: 1 | E14: ='CRU historical'!F13 | F14: ='CRU historical'!I13 -> 11.666667 | G14: ='CRU historical'!L13 | H14: ='CRU historical'!O13 | I14: ='CRU historical'!R13 | J14: =AVERAGE('CRU historical'!U13, 'CRU historical'!X13, 'CRU historical'!AA13, 'CRU historical'!AD13) -> 57.333333 | L14: {=IFERROR(SUMPRODUCT(('Sulphuric Acid freights'!$B$3:$B$513=B14)*('Sulphuric Acid freights'!$D$3:$D$513=D14)*('Sulphuric Acid freights'!$P$3:$P$513))/SUMPRODUCT(('Sulphuric Acid freights'!$B$3:$B$513=B14)*('Sulphuric Acid freights'!$D$3:$D$513=D14)*1), AVERAGE('Sulphuric Acid freights'!$P$3:$P$513))*2/3} -> 54.110672 | M14: {=IFERROR(SUMPRODUCT(('Sulphuric Acid freights'!$B$3:$B$513=B14)*('Sulphuric Acid freights'!$D$3:$D$513=D14)*('Sulphuric Acid freights'!$M$3:$M$513))/SUMPRODUCT(('Sulphuric Acid freights'!$B$3:$B$513=B14)*('Sulphuric Acid freights'!$D$3:$D$513=D14)*1)*2/3, AVERAGE('Sulphuric Acid freights'!$M$3:$M$513))} -> 23.573123 | N14: =IFERROR(L14*0.9, "") -> 48.699605 | O14: {=IF(SUMPRODUCT(('Sulphur freight'!$B$3:$B$1976=B14)*('Sulphur freight'!$D$3:$D$1976=D14)*('Sulphur freight'!$G$3:$G$1976))/SUMPRODUCT(('Sulphur freight'!$B$3:$B$1976=B14)*('Sulphur freight'!$D$3:$D$1976=D14)*1)=0, AVERAGE('Sulphur freight'!$G$3:$G$1976),SUMPRODUCT(('Sulphur freight'!$B$3:$B$1976=B14)*('Sulphur freight'!$D$3:$D$1976=D14)*('Sulphur freight'!$G$3:$G$1976))/SUMPRODUCT(('Sulphur freight'!$B$3:$B$1976=B14)*('Sulphur freight'!$D$3:$D$1976=D14)*1))} -> 29.165429 | P14: 20 | R14: =H14 | S14: =IF(F14=0, "", F14+M14) -> 35.239789 | T14: =IFERROR( E14+L14, "") | U14: =IFERROR( G14+N14, "") | V14: =IFERROR(I14+O14, "") | W14: =J14+P14 -> 77.333333 | X14: =IFERROR((I14+O14)*0.33+18, "") | Y14: =IF(J14=0,0,(J14+P14)*0.33+18) -> 43.52 | AA14: =IF(OR(S14="", T14="", U14=""), "", MAX(R14,S14)*40%+T14*30%+U14*30%) | AB14: =IF(AA14="", "", MAX(X14, Y14)-AA14) | AD14: =IFERROR(MIN((MAX(R14,S14)*70%+U14*30%), Y14), "") | AE14: =IF(AD14="", "", MAX(AA14, AB14)-AD14)
B15: 2003 | C15: 1 | D15: 2 | E15: ='CRU historical'!F14 | F15: ='CRU historical'!I14 -> 13 | G15: ='CRU historical'!L14 | H15: ='CRU historical'!O14 | I15: ='CRU historical'!R14 | J15: =AVERAGE('CRU historical'!U14, 'CRU historical'!X14, 'CRU historical'!AA14, 'CRU historical'!AD14) -> 61 | L15: {=IFERROR(SUMPRODUCT(('Sulphuric Acid freights'!$B$3:$B$513=B15)*('Sulphuric Acid freights'!$D$3:$D$513=D15)*('Sulphuric Acid freights'!$P$3:$P$513))/SUMPRODUCT(('Sulphuric Acid freights'!$B$3:$B$513=B15)*('Sulphuric Acid freights'!$D$3:$D$513=D15)*1), AVERAGE('Sulphuric Acid freights'!$P$3:$P$513))*2/3} -> 54.110672 | M15: {=IFERROR(SUMPRODUCT(('Sulphuric Acid freights'!$B$3:$B$513=B15)*('Sulphuric Acid freights'!$D$3:$D$513=D15)*('Sulphuric Acid freights'!$M$3:$M$513))/SUMPRODUCT(('Sulphuric Acid freights'!$B$3:$B$513=B15)*('Sulphuric Acid freights'!$D$3:$D$513=D15)*1)*2/3, AVERAGE('Sulphuric Acid freights'!$M$3:$M$513))} -> 23.573123 | N15: =IFERROR(L15*0.9, "") -> 48.699605 | O15: {=IF(SUMPRODUCT(('Sulphur freight'!$B$3:$B$1976=B15)*('Sulphur freight'!$D$3:$D$1976=D15)*('Sulphur freight'!$G$3:$G$1976))/SUMPRODUCT(('Sulphur freight'!$B$3:$B$1976=B15)*('Sulphur freight'!$D$3:$D$1976=D15)*1)=0, AVERAGE('Sulphur freight'!$G$3:$G$1976),SUMPRODUCT(('Sulphur freight'!$B$3:$B$1976=B15)*('Sulphur freight'!$D$3:$D$1976=D15)*('Sulphur freight'!$G$3:$G$1976))/SUMPRODUCT(('Sulphur freight'!$B$3:$B$1976=B15)*('Sulphur freight'!$D$3:$D$1976=D15)*1))} -> 29.165429 | P15: 20 | R15: =H15 | S15: =IF(F15=0, "", F15+M15) -> 36.573123 | T15: =IFERROR( E15+L15, "") | U15: =IFERROR( G15+N15, "") | V15: =IFERROR(I15+O15, "") | W15: =J15+P15 -> 81 | X15: =IFERROR((I15+O15)*0.33+18, "") | Y15: =IF(J15=0,0,(J15+P15)*0.33+18) -> 44.73 | AA15: =IF(OR(S15="", T15="", U15=""), "", MAX(R15,S15)*40%+T15*30%+U15*30%) | AB15: =IF(AA15="", "", MAX(X15, Y15)-AA15) | AD15: =IFERROR(MIN((MAX(R15,S15)*70%+U15*30%), Y15), "") | AE15: =IF(AD15="", "", MAX(AA15, AB15)-AD15)
B16: 2003 | C16: 1 | D16: 3 | E16: ='CRU historical'!F15 | F16: ='CRU historical'!I15 -> 13 | G16: ='CRU historical'!L15 | H16: ='CRU historical'!O15 | I16: ='CRU historical'!R15 | J16: =AVERAGE('CRU historical'!U15, 'CRU historical'!X15, 'CRU historical'!AA15, 'CRU historical'!AD15) -> 62 | L16: {=IFERROR(SUMPRODUCT(('Sulphuric Acid freights'!$B$3:$B$513=B16)*('Sulphuric Acid freights'!$D$3:$D$513=D16)*('Sulphuric Acid freights'!$P$3:$P$513))/SUMPRODUCT(('Sulphuric Acid freights'!$B$3:$B$513=B16)*('Sulphuric Acid freights'!$D$3:$D$513=D16)*1), AVERAGE('Sulphuric Acid freights'!$P$3:$P$513))*2/3} -> 54.110672 | M16: {=IFERROR(SUMPRODUCT(('Sulphuric Acid freights'!$B$3:$B$513=B16)*('Sulphuric Acid freights'!$D$3:$D$513=D16)*('Sulphuric Acid freights'!$M$3:$M$513))/SUMPRODUCT(('Sulphuric Acid freights'!$B$3:$B$513=B16)*('Sulphuric Acid freights'!$D$3:$D$513=D16)*1)*2/3, AVERAGE('Sulphuric Acid freights'!$M$3:$M$513))} -> 23.573123 | N16: =IFERROR(L16*0.9, "") -> 48.699605 | O16: {=IF(SUMPRODUCT(('Sulphur freight'!$B$3:$B$1976=B16)*('Sulphur freight'!$D$3:$D$1976=D16)*('Sulphur freight'!$G$3:$G$1976))/SUMPRODUCT(('Sulphur freight'!$B$3:$B$1976=B16)*('Sulphur freight'!$D$3:$D$1976=D16)*1)=0, AVERAGE('Sulphur freight'!$G$3:$G$1976),SUMPRODUCT(('Sulphur freight'!$B$3:$B$1976=B16)*('Sulphur freight'!$D$3:$D$1976=D16)*('Sulphur freight'!$G$3:$G$1976))/SUMPRODUCT(('Sulphur freight'!$B$3:$B$1976=B16)*('Sulphur freight'!$D$3:$D$1976=D16)*1))} -> 29.165429 | P16: 20 | R16: =H16 | S16: =IF(F16=0, "", F16+M16) -> 36.573123 | T16: =IFERROR( E16+L16, "") | U16: =IFERROR( G16+N16, "") | V16: =IFERROR(I16+O16, "") | W16: =J16+P16 -> 82 | X16: =IFERROR((I16+O16)*0.33+18, "") | Y16: =IF(J16=0,0,(J16+P16)*0.33+18) -> 45.06 | AA16: =IF(OR(S16="", T16="", U16=""), "", MAX(R16,S16)*40%+T16*30%+U16*30%) | AB16: =IF(AA16="", "", MAX(X16, Y16)-AA16) | AD16: =IFERROR(MIN((MAX(R16,S16)*70%+U16*30%), Y16), "") | AE16: =IF(AD16="", "", MAX(AA16, AB16)-AD16)
B17: 2003 | C17: 2 | D17: 4 | E17: ='CRU historical'!F16 | F17: ='CRU historical'!I16 -> 13 | G17: ='CRU historical'!L16 | H17: ='CRU historical'!O16 | I17: ='CRU historical'!R16 | J17: =AVERAGE('CRU historical'!U16, 'CRU historical'!X16, 'CRU historical'!AA16, 'CRU historical'!AD16) -> 60.5 | L17: {=IFERROR(SUMPRODUCT(('Sulphuric Acid freights'!$B$3:$B$513=B17)*('Sulphuric Acid freights'!$D$3:$D$513=D17)*('Sulphuric Acid freights'!$P$3:$P$513))/SUMPRODUCT(('Sulphuric Acid freights'!$B$3:$B$513=B17)*('Sulphuric Acid freights'!$D$3:$D$513=D17)*1), AVERAGE('Sulphuric Acid freights'!$P$3:$P$513))*2/3} -> 54.110672 | M17: {=IFERROR(SUMPRODUCT(('Sulphuric Acid freights'!$B$3:$B$513=B17)*('Sulphuric Acid freights'!$D$3:$D$513=D17)*('Sulphuric Acid freights'!$M$3:$M$513))/SUMPRODUCT(('Sulphuric Acid freights'!$B$3:$B$513=B17)*('Sulphuric Acid freights'!$D$3:$D$513=D17)*1)*2/3, AVERAGE('Sulphuric Acid freights'!$M$3:$M$513))} -> 23.573123 | N17: =IFERROR(L17*0.9, "") -> 48.699605 | O17: {=IF(SUMPRODUCT(('Sulphur freight'!$B$3:$B$1976=B17)*('Sulphur freight'!$D$3:$D$1976=D17)*('Sulphur freight'!$G$3:$G$1976))/SUMPRODUCT(('Sulphur freight'!$B$3:$B$1976=B17)*('Sulphur freight'!$D$3:$D$1976=D17)*1)=0, AVERAGE('Sulphur freight'!$G$3:$G$1976),SUMPRODUCT(('Sulphur freight'!$B$3:$B$1976=B17)*('Sulphur freight'!$D$3:$D$1976=D17)*('Sulphur freight'!$G$3:$G$1976))/SUMPRODUCT(('Sulphur freight'!$B$3:$B$1976=B17)*('Sulphur freight'!$D$3:$D$1976=D17)*1))} -> 29.165429 | P17: 20 | R17: =H17 | S17: =IF(F17=0, "", F17+M17) -> 36.573123 | T17: =IFERROR( E17+L17, "") | U17: =IFERROR( G17+N17, "") | V17: =IFERROR(I17+O17, "") | W17: =J17+P17 -> 80.5 | X17: =IFERROR((I17+O17)*0.33+18, "") | Y17: =IF(J17=0,0,(J17+P17)*0.33+18) -> 44.565 | AA17: =IF(OR(S17="", T17="", U17=""), "", MAX(R17,S17)*40%+T17*30%+U17*30%) | AB17: =IF(AA17="", "", MAX(X17, Y17)-AA17) | AD17: =IFERROR(MIN((MAX(R17,S17)*70%+U17*30%), Y17), "") | AE17: =IF(AD17="", "", MAX(AA17, AB17)-AD17)
... B284: 2025 | C284: 3 | D284: 7 | E284: ='CRU historical'!F283 -> 52 | F284: ='CRU historical'!I283 -> 124 | G284: ='CRU historical'!L283 -> 94.2 | H284: ='CRU historical'!O283 -> 170 | I284: ='CRU historical'!R283 -> 260 | J284: =AVERAGE('CRU historical'!U283, 'CRU historical'!X283, 'CRU historical'!AA283, 'CRU historical'!AD283) -> 256 | L284: {=IFERROR(SUMPRODUCT(('Sulphuric Acid freights'!$B$3:$B$513=B284)*('Sulphuric Acid freights'!$D$3:$D$513=D284)*('Sulphuric Acid freights'!$P$3:$P$513))/SUMPRODUCT(('Sulphuric Acid freights'!$B$3:$B$513=B284)*('Sulphuric Acid freights'!$D$3:$D$513=D284)*1), AVERAGE('Sulphuric Acid freights'!$P$3:$P$513))*2/3} -> 67.6 | M284: {=IFERROR(SUMPRODUCT(('Sulphuric Acid freights'!$B$3:$B$513=B284)*('Sulphuric Acid freights'!$D$3:$D$513=D284)*('Sulphuric Acid freights'!$M$3:$M$513))/SUMPRODUCT(('Sulphuric Acid freights'!$B$3:$B$513=B284)*('Sulphuric Acid freights'!$D$3:$D$513=D284)*1)*2/3, AVERAGE('Sulphuric Acid freights'!$M$3:$M$513))} -> 14.666667 | N284: =IFERROR(L284*0.9, "") -> 60.84 | O284: {=IF(SUMPRODUCT(('Sulphur freight'!$B$3:$B$1976=B284)*('Sulphur freight'!$D$3:$D$1976=D284)*('Sulphur freight'!$G$3:$G$1976))/SUMPRODUCT(('Sulphur freight'!$B$3:$B$1976=B284)*('Sulphur freight'!$D$3:$D$1976=D284)*1)=0, AVERAGE('Sulphur freight'!$G$3:$G$1976),SUMPRODUCT(('Sulphur freight'!$B$3:$B$1976=B284)*('Sulphur freight'!$D$3:$D$1976=D284)*('Sulphur freight'!$G$3:$G$1976))/SUMPRODUCT(('Sulphur freight'!$B$3:$B$1976=B284)*('Sulphur freight'!$D$3:$D$1976=D284)*1))} -> 35 | P284: 20 | R284: =H284 -> 170 | S284: =IF(F284=0, "", F284+M284) -> 138.66667 | T284: =IFERROR( E284+L284, "") -> 119.6 | U284: =IFERROR( G284+N284, "") -> 155.04 | V284: =IFERROR(I284+O284, "") -> 295 | W284: =J284+P284 -> 276 | X284: =IFERROR((I284+O284)*0.33+18, "") -> 115.35 | Y284: =IF(J284=0,0,(J284+P284)*0.33+18) -> 109.08 | AA284: =IF(OR(S284="", T284="", U284=""), "", MAX(R284,S284)*40%+T284*30%+U284*30%) -> 150.392 | AB284: =IF(AA284="", "", MAX(X284, Y284)-AA284) -> -35.042 | AD284: =IFERROR(MIN((MAX(R284,S284)*70%+U284*30%), Y284), "") -> 109.08 | AE284: =IF(AD284="", "", MAX(AA284, AB284)-AD284) -> 41.312
B285: 2025 | C285: 3 | D285: 8 | E285: ='CRU historical'!F284 | F285: ='CRU historical'!I284 -> 116.25 | G285: ='CRU historical'!L284 -> 96 | H285: ='CRU historical'!O284 -> 165 | I285: ='CRU historical'!R284 -> 274.75 | J285: =AVERAGE('CRU historical'!U284, 'CRU historical'!X284, 'CRU historical'!AA284, 'CRU historical'!AD284) -> 268 | L285: {=IFERROR(SUMPRODUCT(('Sulphuric Acid freights'!$B$3:$B$513=B285)*('Sulphuric Acid freights'!$D$3:$D$513=D285)*('Sulphuric Acid freights'!$P$3:$P$513))/SUMPRODUCT(('Sulphuric Acid freights'!$B$3:$B$513=B285)*('Sulphuric Acid freights'!$D$3:$D$513=D285)*1), AVERAGE('Sulphuric Acid freights'!$P$3:$P$513))*2/3} -> 66 | M285: {=IFERROR(SUMPRODUCT(('Sulphuric Acid freights'!$B$3:$B$513=B285)*('Sulphuric Acid freights'!$D$3:$D$513=D285)*('Sulphuric Acid freights'!$M$3:$M$513))/SUMPRODUCT(('Sulphuric Acid freights'!$B$3:$B$513=B285)*('Sulphuric Acid freights'!$D$3:$D$513=D285)*1)*2/3, AVERAGE('Sulphuric Acid freights'!$M$3:$M$513))} -> 14.666667 | N285: =IFERROR(L285*0.9, "") -> 59.4 | O285: {=IF(SUMPRODUCT(('Sulphur freight'!$B$3:$B$1976=B285)*('Sulphur freight'!$D$3:$D$1976=D285)*('Sulphur freight'!$G$3:$G$1976))/SUMPRODUCT(('Sulphur freight'!$B$3:$B$1976=B285)*('Sulphur freight'!$D$3:$D$1976=D285)*1)=0, AVERAGE('Sulphur freight'!$G$3:$G$1976),SUMPRODUCT(('Sulphur freight'!$B$3:$B$1976=B285)*('Sulphur freight'!$D$3:$D$1976=D285)*('Sulphur freight'!$G$3:$G$1976))/SUMPRODUCT(('Sulphur freight'!$B$3:$B$1976=B285)*('Sulphur freight'!$D$3:$D$1976=D285)*1))} -> 35.75 | P285: 20 | R285: =H285 -> 165 | S285: =IF(F285=0, "", F285+M285) -> 130.91667 | T285: =T284*(U285/U284) -> 119.87771 | U285: =IFERROR( G285+N285, "") -> 155.4 | V285: =IFERROR(I285+O285, "") -> 310.5 | W285: =J285+P285 -> 288 | X285: =IFERROR((I285+O285)*0.33+18, "") -> 120.465 | Y285: =IF(J285=0,0,(J285+P285)*0.33+18) -> 113.04 | AA285: =IF(OR(S285="", T285="", U285=""), "", MAX(R285,S285)*40%+T285*30%+U285*30%) -> 148.58331 | AB285: =IF(AA285="", "", MAX(X285, Y285)-AA285) -> -28.118313 | AD285: =IFERROR(MIN((MAX(R285,S285)*70%+U285*30%), Y285), "") -> 113.04 | AE285: =IF(AD285="", "", MAX(AA285, AB285)-AD285) -> 35.543313
B286: 2025 | C286: 3 | D286: 9 | E286: ='CRU historical'!F285 | F286: ='CRU historical'!I285 -> 79.5 | G286: ='CRU historical'!L285 -> 76 | H286: ='CRU historical'!O285 -> 130 | I286: ='CRU historical'!R285 -> 307.75 | J286: =AVERAGE('CRU historical'!U285, 'CRU historical'!X285, 'CRU historical'!AA285, 'CRU historical'!AD285) -> 268 | L286: {=IFERROR(SUMPRODUCT(('Sulphuric Acid freights'!$B$3:$B$513=B286)*('Sulphuric Acid freights'!$D$3:$D$513=D286)*('Sulphuric Acid freights'!$P$3:$P$513))/SUMPRODUCT(('Sulphuric Acid freights'!$B$3:$B$513=B286)*('Sulphuric Acid freights'!$D$3:$D$513=D286)*1), AVERAGE('Sulphuric Acid freights'!$P$3:$P$513))*2/3} -> 66 | M286: {=IFERROR(SUMPRODUCT(('Sulphuric Acid freights'!$B$3:$B$513=B286)*('Sulphuric Acid freights'!$D$3:$D$513=D286)*('Sulphuric Acid freights'!$M$3:$M$513))/SUMPRODUCT(('Sulphuric Acid freights'!$B$3:$B$513=B286)*('Sulphuric Acid freights'!$D$3:$D$513=D286)*1)*2/3, AVERAGE('Sulphuric Acid freights'!$M$3:$M$513))} -> 14.666667 | N286: =IFERROR(L286*0.9, "") -> 59.4 | O286: {=IF(SUMPRODUCT(('Sulphur freight'!$B$3:$B$1976=B286)*('Sulphur freight'!$D$3:$D$1976=D286)*('Sulphur freight'!$G$3:$G$1976))/SUMPRODUCT(('Sulphur freight'!$B$3:$B$1976=B286)*('Sulphur freight'!$D$3:$D$1976=D286)*1)=0, AVERAGE('Sulphur freight'!$G$3:$G$1976),SUMPRODUCT(('Sulphur freight'!$B$3:$B$1976=B286)*('Sulphur freight'!$D$3:$D$1976=D286)*('Sulphur freight'!$G$3:$G$1976))/SUMPRODUCT(('Sulphur freight'!$B$3:$B$1976=B286)*('Sulphur freight'!$D$3:$D$1976=D286)*1))} -> 35.5 | P286: 20 | R286: =H286 -> 130 | S286: =IF(F286=0, "", F286+M286) -> 94.166667 | T286: =T285*(U286/U285) -> 104.44943 | U286: =IFERROR( G286+N286, "") -> 135.4 | V286: =IFERROR(I286+O286, "") -> 343.25 | W286: =J286+P286 -> 288 | X286: =IFERROR((I286+O286)*0.33+18, "") -> 131.2725 | Y286: =IF(J286=0,0,(J286+P286)*0.33+18) -> 113.04 | AA286: =IF(OR(S286="", T286="", U286=""), "", MAX(R286,S286)*40%+T286*30%+U286*30%) -> 123.95483 | AB286: =IF(AA286="", "", MAX(X286, Y286)-AA286) -> 7.3176703 | AD286: =IFERROR(MIN((MAX(R286,S286)*70%+U286*30%), Y286), "") -> 113.04 | AE286: =IF(AD286="", "", MAX(AA286, AB286)-AD286) -> 10.91483
B287: 2025 | C287: 4 | D287: 10 | E287: ='CRU historical'!F286 | F287: ='CRU historical'!I286 -> 80.2 | G287: ='CRU historical'!L286 -> 79.2 | H287: ='CRU historical'!O286 -> 130 | I287: ='CRU historical'!R286 -> 359.8 | J287: =AVERAGE('CRU historical'!U286, 'CRU historical'!X286, 'CRU historical'!AA286, 'CRU historical'!AD286) -> 301.6 | L287: {=IFERROR(SUMPRODUCT(('Sulphuric Acid freights'!$B$3:$B$513=B287)*('Sulphuric Acid freights'!$D$3:$D$513=D287)*('Sulphuric Acid freights'!$P$3:$P$513))/SUMPRODUCT(('Sulphuric Acid freights'!$B$3:$B$513=B287)*('Sulphuric Acid freights'!$D$3:$D$513=D287)*1), AVERAGE('Sulphuric Acid freights'!$P$3:$P$513))*2/3} -> 66 | M287: {=IFERROR(SUMPRODUCT(('Sulphuric Acid freights'!$B$3:$B$513=B287)*('Sulphuric Acid freights'!$D$3:$D$513=D287)*('Sulphuric Acid freights'!$M$3:$M$513))/SUMPRODUCT(('Sulphuric Acid freights'!$B$3:$B$513=B287)*('Sulphuric Acid freights'!$D$3:$D$513=D287)*1)*2/3, AVERAGE('Sulphuric Acid freights'!$M$3:$M$513))} -> 13.6 | N287: =IFERROR(L287*0.9, "") -> 59.4 | O287: {=IF(SUMPRODUCT(('Sulphur freight'!$B$3:$B$1976=B287)*('Sulphur freight'!$D$3:$D$1976=D287)*('Sulphur freight'!$G$3:$G$1976))/SUMPRODUCT(('Sulphur freight'!$B$3:$B$1976=B287)*('Sulphur freight'!$D$3:$D$1976=D287)*1)=0, AVERAGE('Sulphur freight'!$G$3:$G$1976),SUMPRODUCT(('Sulphur freight'!$B$3:$B$1976=B287)*('Sulphur freight'!$D$3:$D$1976=D287)*('Sulphur freight'!$G$3:$G$1976))/SUMPRODUCT(('Sulphur freight'!$B$3:$B$1976=B287)*('Sulphur freight'!$D$3:$D$1976=D287)*1))} -> 31 | P287: 20 | R287: =H287 -> 130 | S287: =IF(F287=0, "", F287+M287) -> 93.8 | T287: =T286*(U287/U286) -> 106.91796 | U287: =IFERROR( G287+N287, "") -> 138.6 | V287: =IFERROR(I287+O287, "") -> 390.8 | W287: =J287+P287 -> 321.6 | X287: =IFERROR((I287+O287)*0.33+18, "") -> 146.964 | Y287: =IF(J287=0,0,(J287+P287)*0.33+18) -> 124.128 | AA287: =IF(OR(S287="", T287="", U287=""), "", MAX(R287,S287)*40%+T287*30%+U287*30%) -> 125.65539 | AB287: =IF(AA287="", "", MAX(X287, Y287)-AA287) -> 21.308613 | AD287: =IFERROR(MIN((MAX(R287,S287)*70%+U287*30%), Y287), "") -> 124.128 | AE287: =IF(AD287="", "", MAX(AA287, AB287)-AD287) -> 1.527387
B288: 2025 | C288: 4 | D288: 11 | E288: ='CRU historical'!F287 | F288: ='CRU historical'!I287 -> 97.75 | G288: ='CRU historical'!L287 -> 105.75 | H288: ='CRU historical'!O287 -> 132.5 | I288: ='CRU historical'!R287 -> 452 | J288: =AVERAGE('CRU historical'!U287, 'CRU historical'!X287, 'CRU historical'!AA287, 'CRU historical'!AD287) -> 310 | L288: {=IFERROR(SUMPRODUCT(('Sulphuric Acid freights'!$B$3:$B$513=B288)*('Sulphuric Acid freights'!$D$3:$D$513=D288)*('Sulphuric Acid freights'!$P$3:$P$513))/SUMPRODUCT(('Sulphuric Acid freights'!$B$3:$B$513=B288)*('Sulphuric Acid freights'!$D$3:$D$513=D288)*1), AVERAGE('Sulphuric Acid freights'!$P$3:$P$513))*2/3} -> 66 | M288: {=IFERROR(SUMPRODUCT(('Sulphuric Acid freights'!$B$3:$B$513=B288)*('Sulphuric Acid freights'!$D$3:$D$513=D288)*('Sulphuric Acid freights'!$M$3:$M$513))/SUMPRODUCT(('Sulphuric Acid freights'!$B$3:$B$513=B288)*('Sulphuric Acid freights'!$D$3:$D$513=D288)*1)*2/3, AVERAGE('Sulphuric Acid freights'!$M$3:$M$513))} -> 14.666667 | N288: =IFERROR(L288*0.9, "") -> 59.4 | O288: {=IF(SUMPRODUCT(('Sulphur freight'!$B$3:$B$1976=B288)*('Sulphur freight'!$D$3:$D$1976=D288)*('Sulphur freight'!$G$3:$G$1976))/SUMPRODUCT(('Sulphur freight'!$B$3:$B$1976=B288)*('Sulphur freight'!$D$3:$D$1976=D288)*1)=0, AVERAGE('Sulphur freight'!$G$3:$G$1976),SUMPRODUCT(('Sulphur freight'!$B$3:$B$1976=B288)*('Sulphur freight'!$D$3:$D$1976=D288)*('Sulphur freight'!$G$3:$G$1976))/SUMPRODUCT(('Sulphur freight'!$B$3:$B$1976=B288)*('Sulphur freight'!$D$3:$D$1976=D288)*1))} -> 32 | P288: 20 | R288: =H288 -> 132.5 | S288: =IF(F288=0, "", F288+M288) -> 112.41667 | T288: =T287*(U288/U287) -> 127.39899 | U288: =IFERROR( G288+N288, "") -> 165.15 | V288: =IFERROR(I288+O288, "") -> 484 | W288: =J288+P288 -> 330 | X288: =IFERROR((I288+O288)*0.33+18, "") -> 177.72 | Y288: =IF(J288=0,0,(J288+P288)*0.33+18) -> 126.9 | AA288: =IF(OR(S288="", T288="", U288=""), "", MAX(R288,S288)*40%+T288*30%+U288*30%) -> 140.7647 | AB288: =IF(AA288="", "", MAX(X288, Y288)-AA288) -> 36.955302 | AD288: =IFERROR(MIN((MAX(R288,S288)*70%+U288*30%), Y288), "") -> 126.9 | AE288: =IF(AD288="", "", MAX(AA288, AB288)-AD288) -> 13.864698
B289: 2025 | C289: 4 | D289: 12 | E289: ='CRU historical'!F288 | F289: ='CRU historical'!I288 -> 106 | G289: ='CRU historical'!L288 -> 113 | H289: ='CRU historical'!O288 -> 136 | I289: ='CRU historical'!R288 -> 507 | J289: =AVERAGE('CRU historical'!U288, 'CRU historical'!X288, 'CRU historical'!AA288, 'CRU historical'!AD288) -> 310 | L289: {=IFERROR(SUMPRODUCT(('Sulphuric Acid freights'!$B$3:$B$513=B289)*('Sulphuric Acid freights'!$D$3:$D$513=D289)*('Sulphuric Acid freights'!$P$3:$P$513))/SUMPRODUCT(('Sulphuric Acid freights'!$B$3:$B$513=B289)*('Sulphuric Acid freights'!$D$3:$D$513=D289)*1), AVERAGE('Sulphuric Acid freights'!$P$3:$P$513))*2/3} -> 66 | M289: {=IFERROR(SUMPRODUCT(('Sulphuric Acid freights'!$B$3:$B$513=B289)*('Sulphuric Acid freights'!$D$3:$D$513=D289)*('Sulphuric Acid freights'!$M$3:$M$513))/SUMPRODUCT(('Sulphuric Acid freights'!$B$3:$B$513=B289)*('Sulphuric Acid freights'!$D$3:$D$513=D289)*1)*2/3, AVERAGE('Sulphuric Acid freights'!$M$3:$M$513))} -> 14.666667 | N289: =IFERROR(L289*0.9, "") -> 59.4 | O289: {=IF(SUMPRODUCT(('Sulphur freight'!$B$3:$B$1976=B289)*('Sulphur freight'!$D$3:$D$1976=D289)*('Sulphur freight'!$G$3:$G$1976))/SUMPRODUCT(('Sulphur freight'!$B$3:$B$1976=B289)*('Sulphur freight'!$D$3:$D$1976=D289)*1)=0, AVERAGE('Sulphur freight'!$G$3:$G$1976),SUMPRODUCT(('Sulphur freight'!$B$3:$B$1976=B289)*('Sulphur freight'!$D$3:$D$1976=D289)*('Sulphur freight'!$G$3:$G$1976))/SUMPRODUCT(('Sulphur freight'!$B$3:$B$1976=B289)*('Sulphur freight'!$D$3:$D$1976=D289)*1))} -> 32.666667 | P289: 20 | R289: =H289 -> 136 | S289: =IF(F289=0, "", F289+M289) -> 120.66667 | T289: =T288*(U289/U288) -> 132.99174 | U289: =IFERROR( G289+N289, "") -> 172.4 | V289: =IFERROR(I289+O289, "") -> 539.66667 | W289: =J289+P289 -> 330 | X289: =IFERROR(V289*0.33+18, "") -> 196.09 | Y289: =IF(J289=0,0,W289*0.33+18) -> 126.9 | AA289: =IF(OR(S289="", T289="", U289=""), "", MAX(R289,S289)*40%+T289*30%+U289*30%) -> 146.01752 | AB289: =IF(AA289="", "", MAX(X289, Y289)-AA289) -> 50.072477 | AD289: =IFERROR(MIN((MAX(R289,S289)*70%+U289*30%), Y289), "") -> 126.9 | AE289: =IF(AD289="", "", MAX(AA289, AB289)-AD289) -> 19.117523
B291: 2026 | S291: ='ACS - CRU Outlook'!D18 -> 83.482143 | T291: ='ACS - CRU Outlook'!H18+'Simulateur sur Avg'!$L$289 -> 155.67083 | U291: ='ACS - CRU Outlook'!I18+'Simulateur sur Avg'!$N$289 -> 143.65417 | V291: ='S - CRU Outlook'!C18+$O$289 -> 384.95976 | W291: ='S - CRU Outlook'!J18+$P$289 -> 384.31322 | X291: =V291*0.33+18 -> 145.03672 | Y291: =W291*0.33+18 -> 144.82336 | AA291: =IF(OR(S291="", T291="", U291=""), "", MAX(R291,S291)*40%+T291*30%+U291*30%) -> 123.19036 | AB291: =IF(AA291="", "", MAX(X291, Y291)-AA291) -> 21.846365 | AD291: =IFERROR(MIN((MAX(R291,S291)*70%+U291*30%), Y291), "") -> 101.53375 | AE291: =IF(AD291="", "", MAX(AA291, AB291)-AD291) -> 21.656607
B292: 2027 | S292: ='ACS - CRU Outlook'!D19 -> 80.929219 | T292: ='ACS - CRU Outlook'!H19+'Simulateur sur Avg'!$L$289 -> 125.92922 | U292: ='ACS - CRU Outlook'!I19+'Simulateur sur Avg'!$N$289 -> 125.32922 | V292: ='S - CRU Outlook'!C19+$O$289 -> 274.13203 | W292: ='S - CRU Outlook'!J19+$P$289 -> 273.30844 | X292: =V292*0.33+18 -> 108.46357 | Y292: =W292*0.33+18 -> 108.19178 | AA292: =IF(OR(S292="", T292="", U292=""), "", MAX(R292,S292)*40%+T292*30%+U292*30%) -> 107.74922 | AB292: =IF(AA292="", "", MAX(X292, Y292)-AA292) -> 0.71435076 | AD292: =IFERROR(MIN((MAX(R292,S292)*70%+U292*30%), Y292), "") -> 94.249219 | AE292: =IF(AD292="", "", MAX(AA292, AB292)-AD292) -> 13.5
B293: 2028 | S293: ='ACS - CRU Outlook'!D20 -> 66.644459 | T293: ='ACS - CRU Outlook'!H20+'Simulateur sur Avg'!$L$289 -> 120.64446 | U293: ='ACS - CRU Outlook'!I20+'Simulateur sur Avg'!$N$289 -> 120.04446 | V293: ='S - CRU Outlook'!C20+$O$289 -> 246.8432 | W293: ='S - CRU Outlook'!J20+$P$289 -> 246.23543 | X293: =V293*0.33+18 -> 99.458256 | Y293: =W293*0.33+18 -> 99.257691 | AA293: =IF(OR(S293="", T293="", U293=""), "", MAX(R293,S293)*40%+T293*30%+U293*30%) -> 98.864459 | AB293: =IF(AA293="", "", MAX(X293, Y293)-AA293) -> 0.59379657 | AD293: =IFERROR(MIN((MAX(R293,S293)*70%+U293*30%), Y293), "") -> 82.664459 | AE293: =IF(AD293="", "", MAX(AA293, AB293)-AD293) -> 16.2
B294: 2029 | S294: ='ACS - CRU Outlook'!D21 -> 65.394434 | T294: ='ACS - CRU Outlook'!H21+'Simulateur sur Avg'!$L$289 -> 114.39443 | U294: ='ACS - CRU Outlook'!I21+'Simulateur sur Avg'!$N$289 -> 113.79443 | V294: ='S - CRU Outlook'!C21+$O$289 -> 239.17879 | W294: ='S - CRU Outlook'!J21+$P$289 -> 238.64587 | X294: =V294*0.33+18 -> 96.929001 | Y294: =W294*0.33+18 -> 96.753136 | AA294: =IF(OR(S294="", T294="", U294=""), "", MAX(R294,S294)*40%+T294*30%+U294*30%) -> 94.614434 | AB294: =IF(AA294="", "", MAX(X294, Y294)-AA294) -> 2.3145674 | AD294: =IFERROR(MIN((MAX(R294,S294)*70%+U294*30%), Y294), "") -> 79.914434 | AE294: =IF(AD294="", "", MAX(AA294, AB294)-AD294) -> 14.7
B295: 2030 | S295: ='ACS - CRU Outlook'!D22 -> 61.438116 | T295: ='ACS - CRU Outlook'!H22+'Simulateur sur Avg'!$L$289 -> 108.43812 | U295: ='ACS - CRU Outlook'!I22+'Simulateur sur Avg'!$N$289 -> 107.83812 | V295: ='S - CRU Outlook'!C22+$O$289 -> 243.75994 | W295: ='S - CRU Outlook'!J22+$P$289 -> 243.21409 | X295: =V295*0.33+18 -> 98.440779 | Y295: =W295*0.33+18 -> 98.260649 | AA295: =IF(OR(S295="", T295="", U295=""), "", MAX(R295,S295)*40%+T295*30%+U295*30%) -> 89.458116 | AB295: =IF(AA295="", "", MAX(X295, Y295)-AA295) -> 8.9826628 | AD295: =IFERROR(MIN((MAX(R295,S295)*70%+U295*30%), Y295), "") -> 75.358116 | AE295: =IF(AD295="", "", MAX(AA295, AB295)-AD295) -> 14.1
B296: 2031
B297: 2032
B298: 2033
B299: 2034
B300: 2035
B301: 2036
B302: 2037

Sheet Simulateur furu
AA1: ConvCost=20+0,05×(SFOBME​+Fret)
B2: Scénario | C2: Low | D2: 0.8 | J2: used for ACS production cost estimation
R3: Paramètres
R5: Futur
B12: Projections annuelles moyennes | E12: ACS FOB Japan | F12: ACS FOB NW Europe | G12: ACS FOB China Spot | H12: ACS CFR North Africa Spot | I12: Sulphur Bulk FOB Middle East | J12: Sulphur Bulk CFR North Africa | L12: Fret Japan to Morocco | M12: Fret NW EU to Morocco | N12: Fret China to Morocco | O12: Fret Middle East to Morocco | P12: Freight adjustment (CRU)
B13: 2026 | E13: ='ACS - CRU Outlook'!H18 -> 89.670833 | F13: ='ACS - CRU Outlook'!D18 -> 83.482143 | G13: ='ACS - CRU Outlook'!I18 -> 84.254167 | H13: =F13+25 -> 108.48214 | I13: ='S - CRU Outlook'!C18 -> 352.2931 | J13: ='S - CRU Outlook'!J18 -> 364.31322 | L13: =AVERAGE(L301:L311) -> 70.069697 | M13: =AVERAGE(M301:M311) -> 15.145455 | N13: =AVERAGE(N301:N311) -> 63.062727 | O13: =AVERAGE(O301:O311) -> 32.701515 | P13: =AVERAGE(P301:P311) -> 20
B14: 2027 | E14: ='ACS - CRU Outlook'!H19 -> 59.929219 | F14: ='ACS - CRU Outlook'!D19 -> 80.929219 | G14: ='ACS - CRU Outlook'!I19 -> 65.929219 | H14: =F14+25 -> 105.92922 | I14: ='S - CRU Outlook'!C19 -> 241.46536 | J14: ='S - CRU Outlook'!J19 -> 253.30844 | L14: =L13 -> 70.069697 | M14: =M13 -> 15.145455 | N14: =N13 -> 63.062727 | O14: =O13 -> 32.701515 | P14: =P13 -> 20
B15: 2028 | E15: ='ACS - CRU Outlook'!H20 -> 54.644459 | F15: ='ACS - CRU Outlook'!D20 -> 66.644459 | G15: ='ACS - CRU Outlook'!I20 -> 60.644459 | H15: =F15+25 -> 91.644459 | I15: ='S - CRU Outlook'!C20 -> 214.17653 | J15: ='S - CRU Outlook'!J20 -> 226.23543 | L15: =L14 -> 70.069697 | M15: =M14 -> 15.145455 | N15: =N14 -> 63.062727 | O15: =O14 -> 32.701515 | P15: =P14 -> 20
B16: 2029 | E16: ='ACS - CRU Outlook'!H21 -> 48.394434 | F16: ='ACS - CRU Outlook'!D21 -> 65.394434 | G16: ='ACS - CRU Outlook'!I21 -> 54.394434 | H16: =F16+25 -> 90.394434 | I16: ='S - CRU Outlook'!C21 -> 206.51213 | J16: ='S - CRU Outlook'!J21 -> 218.64587 | L16: =L15 -> 70.069697 | M16: =M15 -> 15.145455 | N16: =N15 -> 63.062727 | O16: =O15 -> 32.701515 | P16: =P15 -> 20
B17: 2030 | E17: ='ACS - CRU Outlook'!H22 -> 42.438116 | F17: ='ACS - CRU Outlook'!D22 -> 61.438116 | G17: ='ACS - CRU Outlook'!I22 -> 48.438116 | H17: =F17+25 -> 86.438116 | I17: ='S - CRU Outlook'!C22 -> 211.09327 | J17: ='S - CRU Outlook'!J22 -> 223.21409 | L17: =L16 -> 70.069697 | M17: =M16 -> 15.145455 | N17: =N16 -> 63.062727 | O17: =O16 -> 32.701515 | P17: =P16 -> 20
B18: 2031 | E18: =E17 -> 42.438116 | F18: =F17 -> 61.438116 | G18: =G17 -> 48.438116 | H18: =H17 -> 86.438116 | I18: =I17 -> 211.09327 | J18: =J17 -> 223.21409 | L18: =L17 -> 70.069697 | M18: =M17 -> 15.145455 | N18: =N17 -> 63.062727 | O18: =O17 -> 32.701515 | P18: =P17 -> 20
B19: 2032 | E19: =E18 -> 42.438116 | F19: =F18 -> 61.438116 | G19: =G18 -> 48.438116 | H19: =H18 -> 86.438116 | I19: =I18 -> 211.09327 | J19: =J18 -> 223.21409 | L19: =L18 -> 70.069697 | M19: =M18 -> 15.145455 | N19: =N18 -> 63.062727 | O19: =O18 -> 32.701515 | P19: =P18 -> 20
B20: 2033 | E20: =E19 -> 42.438116 | F20: =F19 -> 61.438116 | G20: =G19 -> 48.438116 | H20: =H19 -> 86.438116 | I20: =I19 -> 211.09327 | J20: =J19 -> 223.21409 | L20: =L19 -> 70.069697 | M20: =M19 -> 15.145455 | N20: =N19 -> 63.062727 | O20: =O19 -> 32.701515 | P20: =P19 -> 20
B21: 2034 | E21: =E20 -> 42.438116 | F21: =F20 -> 61.438116 | G21: =G20 -> 48.438116 | H21: =H20 -> 86.438116 | I21: =I20 -> 211.09327 | J21: =J20 -> 223.21409 | L21: =L20 -> 70.069697 | M21: =M20 -> 15.145455 | N21: =N20 -> 63.062727 | O21: =O20 -> 32.701515 | P21: =P20 -> 20
B22: 2035 | E22: =E21 -> 42.438116 | F22: =F21 -> 61.438116 | G22: =G21 -> 48.438116 | H22: =H21 -> 86.438116 | I22: =I21 -> 211.09327 | J22: =J21 -> 223.21409 | L22: =L21 -> 70.069697 | M22: =M21 -> 15.145455 | N22: =N21 -> 63.062727 | O22: =O21 -> 32.701515 | P22: =P21 -> 20
B23: 2036 | E23: =E22 -> 42.438116 | F23: =F22 -> 61.438116 | G23: =G22 -> 48.438116 | H23: =H22 -> 86.438116 | I23: =I22 -> 211.09327 | J23: =J22 -> 223.21409 | L23: =L22 -> 70.069697 | M23: =M22 -> 15.145455 | N23: =N22 -> 63.062727 | O23: =O22 -> 32.701515 | P23: =P22 -> 20
E25: Sulphuric Acid Bulk FOB | F25: Sulphuric Acid Bulk FOB | G25: Sulphuric Acid Bulk FOB | H25: Sulphuric Acid Bulk CFR | I25: Sulphur Bulk FOB | J25: Sulphur Bulk CFR | L25: Sulphuric Acid Bulk FOB | M25: Sulphuric Acid Bulk FOB | N25: Sulphuric Acid Bulk FOB | O25: Sulphur Bulk FOB | P25: Sulphur Bulk CFR
E26: Japan/South Korea Spot | F26: NW Europe 30 days Spot | G26: China Spot | H26: North Africa, Spot | I26: Middle East Spot | J26: North Africa | L26: Japan/South Korea Spot | M26: NW Europe 30 days Spot | N26: China Spot | O26: Middle East Spot | P26: North Africa | R26: Prix cibles Sulphuric Acid | AA26: Formule 1: Market Basket | AD26: Formule 2: Indice Composite basé sur Europe, chine et acid base ME
C27: Quarter | D27: Month | E27: ACS FOB Japan | F27: ACS FOB NW Europe | G27: ACS FOB China Spot | H27: ACS CFR North Africa Spot | I27: Sulphur Bulk FOB Middle East | J27: Sulphur Bulk CFR North Africa | L27: Fret Japan to Morocco | M27: Fret NW EU to Morocco | N27: Fret China to Morocco | O27: Fret Middle East to Morocco | P27: Freight adjustment (CRU) | R27: ACS CFR North Africa | S27: IPP ACS Origine Europe | T27: IPP ACS origine Japon | U27: Ipp ACS Origine Chine | V27: Sulfur ME to CFR Morocco | W27: Sulfur North Africa to CFR Morocco | X27: ACS S based from Sulfur ME | Y27: ACS S based from Sulfur North Africa | AA27: IPP_Acid = 40% × IPP_NWE + 30% × IPP_Japan + 30% × IPP_China | AB27: Gain par rapport à production sur place | AD27: IPP_Acid = min((70% × IPP_NWE + 30% × IPP_China); Acid S Based ME) | AE27: Gain par rapport à production sur place
C28: 2 | D28: 5 | E28: ='CRU historical'!F5 | F28: ='CRU historical'!I5 -> 6 | G28: ='CRU historical'!L5 | H28: ='CRU historical'!O5 | I28: ='CRU historical'!R5 | J28: =AVERAGE('CRU historical'!U5, 'CRU historical'!X5, 'CRU historical'!AA5, 'CRU historical'!AD5) -> 33 | L28: {=IFERROR(SUMPRODUCT(('Sulphuric Acid freights'!$B$3:$B$513=B38)*('Sulphuric Acid freights'!$D$3:$D$513=D28)*('Sulphuric Acid freights'!$P$3:$P$513))/SUMPRODUCT(('Sulphuric Acid freights'!$B$3:$B$513=B38)*('Sulphuric Acid freights'!$D$3:$D$513=D28)*1), AVERAGE('Sulphuric Acid freights'!$P$3:$P$513))*2/3} -> 54.110672 | M28: {=IFERROR(SUMPRODUCT(('Sulphuric Acid freights'!$B$3:$B$513=B38)*('Sulphuric Acid freights'!$D$3:$D$513=D28)*('Sulphuric Acid freights'!$M$3:$M$513))/SUMPRODUCT(('Sulphuric Acid freights'!$B$3:$B$513=B38)*('Sulphuric Acid freights'!$D$3:$D$513=D28)*1)*2/3, AVERAGE('Sulphuric Acid freights'!$M$3:$M$513))} -> 23.573123 | N28: =IFERROR(L28*0.9, "") -> 48.699605 | O28: {=IF(SUMPRODUCT(('Sulphur freight'!$B$3:$B$1976=B38)*('Sulphur freight'!$D$3:$D$1976=D28)*('Sulphur freight'!$G$3:$G$1976))/SUMPRODUCT(('Sulphur freight'!$B$3:$B$1976=B38)*('Sulphur freight'!$D$3:$D$1976=D28)*1)=0, AVERAGE('Sulphur freight'!$G$3:$G$1976),SUMPRODUCT(('Sulphur freight'!$B$3:$B$1976=B38)*('Sulphur freight'!$D$3:$D$1976=D28)*('Sulphur freight'!$G$3:$G$1976))/SUMPRODUCT(('Sulphur freight'!$B$3:$B$1976=B38)*('Sulphur freight'!$D$3:$D$1976=D28)*1))} -> 29.165429 | P28: 20 | R28: =H28 | S28: =IF(F28=0, "", F28+M28) -> 29.573123 | T28: =IFERROR( E28+L28, "") | U28: =IFERROR( G28+N28, "") | V28: =IFERROR(I28+O28, "") | W28: =J28+P28 -> 53 | X28: =IFERROR((I28+O28)*0.33+18, "") | Y28: =IF(J28=0,0,(J28+P28)*0.33+18) -> 35.49 | AA28: =IF(OR(S28="", T28="", U28=""), "", MAX(R28,S28)*40%+T28*30%+U28*30%) | AB28: =IF(AA28="", "", MAX(X28, Y28)-AA28) | AD28: =IFERROR(MIN((MAX(R28,S28)*70%+U28*30%), Y28), "") | AE28: =IF(AD28="", "", MAX(AA28, AB28)-AD28)
C29: 2 | D29: 6 | E29: ='CRU historical'!F6 | F29: ='CRU historical'!I6 -> 6 | G29: ='CRU historical'!L6 | H29: ='CRU historical'!O6 | I29: ='CRU historical'!R6 | J29: =AVERAGE('CRU historical'!U6, 'CRU historical'!X6, 'CRU historical'!AA6, 'CRU historical'!AD6) -> 33 | L29: {=IFERROR(SUMPRODUCT(('Sulphuric Acid freights'!$B$3:$B$513=B39)*('Sulphuric Acid freights'!$D$3:$D$513=D29)*('Sulphuric Acid freights'!$P$3:$P$513))/SUMPRODUCT(('Sulphuric Acid freights'!$B$3:$B$513=B39)*('Sulphuric Acid freights'!$D$3:$D$513=D29)*1), AVERAGE('Sulphuric Acid freights'!$P$3:$P$513))*2/3} -> 54.110672 | M29: {=IFERROR(SUMPRODUCT(('Sulphuric Acid freights'!$B$3:$B$513=B39)*('Sulphuric Acid freights'!$D$3:$D$513=D29)*('Sulphuric Acid freights'!$M$3:$M$513))/SUMPRODUCT(('Sulphuric Acid freights'!$B$3:$B$513=B39)*('Sulphuric Acid freights'!$D$3:$D$513=D29)*1)*2/3, AVERAGE('Sulphuric Acid freights'!$M$3:$M$513))} -> 23.573123 | N29: =IFERROR(L29*0.9, "") -> 48.699605 | O29: {=IF(SUMPRODUCT(('Sulphur freight'!$B$3:$B$1976=B39)*('Sulphur freight'!$D$3:$D$1976=D29)*('Sulphur freight'!$G$3:$G$1976))/SUMPRODUCT(('Sulphur freight'!$B$3:$B$1976=B39)*('Sulphur freight'!$D$3:$D$1976=D29)*1)=0, AVERAGE('Sulphur freight'!$G$3:$G$1976),SUMPRODUCT(('Sulphur freight'!$B$3:$B$1976=B39)*('Sulphur freight'!$D$3:$D$1976=D29)*('Sulphur freight'!$G$3:$G$1976))/SUMPRODUCT(('Sulphur freight'!$B$3:$B$1976=B39)*('Sulphur freight'!$D$3:$D$1976=D29)*1))} -> 29.165429 | P29: 20 | R29: =H29 | S29: =IF(F29=0, "", F29+M29) -> 29.573123 | T29: =IFERROR( E29+L29, "") | U29: =IFERROR( G29+N29, "") | V29: =IFERROR(I29+O29, "") | W29: =J29+P29 -> 53 | X29: =IFERROR((I29+O29)*0.33+18, "") | Y29: =IF(J29=0,0,(J29+P29)*0.33+18) -> 35.49 | AA29: =IF(OR(S29="", T29="", U29=""), "", MAX(R29,S29)*40%+T29*30%+U29*30%) | AB29: =IF(AA29="", "", MAX(X29, Y29)-AA29) | AD29: =IFERROR(MIN((MAX(R29,S29)*70%+U29*30%), Y29), "") | AE29: =IF(AD29="", "", MAX(AA29, AB29)-AD29)
C30: 3 | D30: 7 | E30: ='CRU historical'!F7 | F30: ='CRU historical'!I7 -> 8 | G30: ='CRU historical'!L7 | H30: ='CRU historical'!O7 | I30: ='CRU historical'!R7 | J30: =AVERAGE('CRU historical'!U7, 'CRU historical'!X7, 'CRU historical'!AA7, 'CRU historical'!AD7) -> 39 | L30: {=IFERROR(SUMPRODUCT(('Sulphuric Acid freights'!$B$3:$B$513=B40)*('Sulphuric Acid freights'!$D$3:$D$513=D30)*('Sulphuric Acid freights'!$P$3:$P$513))/SUMPRODUCT(('Sulphuric Acid freights'!$B$3:$B$513=B40)*('Sulphuric Acid freights'!$D$3:$D$513=D30)*1), AVERAGE('Sulphuric Acid freights'!$P$3:$P$513))*2/3} -> 54.110672 | M30: {=IFERROR(SUMPRODUCT(('Sulphuric Acid freights'!$B$3:$B$513=B40)*('Sulphuric Acid freights'!$D$3:$D$513=D30)*('Sulphuric Acid freights'!$M$3:$M$513))/SUMPRODUCT(('Sulphuric Acid freights'!$B$3:$B$513=B40)*('Sulphuric Acid freights'!$D$3:$D$513=D30)*1)*2/3, AVERAGE('Sulphuric Acid freights'!$M$3:$M$513))} -> 23.573123 | N30: =IFERROR(L30*0.9, "") -> 48.699605 | O30: {=IF(SUMPRODUCT(('Sulphur freight'!$B$3:$B$1976=B40)*('Sulphur freight'!$D$3:$D$1976=D30)*('Sulphur freight'!$G$3:$G$1976))/SUMPRODUCT(('Sulphur freight'!$B$3:$B$1976=B40)*('Sulphur freight'!$D$3:$D$1976=D30)*1)=0, AVERAGE('Sulphur freight'!$G$3:$G$1976),SUMPRODUCT(('Sulphur freight'!$B$3:$B$1976=B40)*('Sulphur freight'!$D$3:$D$1976=D30)*('Sulphur freight'!$G$3:$G$1976))/SUMPRODUCT(('Sulphur freight'!$B$3:$B$1976=B40)*('Sulphur freight'!$D$3:$D$1976=D30)*1))} -> 29.165429 | P30: 20 | R30: =H30 | S30: =IF(F30=0, "", F30+M30) -> 31.573123 | T30: =IFERROR( E30+L30, "") | U30: =IFERROR( G30+N30, "") | V30: =IFERROR(I30+O30, "") | W30: =J30+P30 -> 59 | X30: =IFERROR((I30+O30)*0.33+18, "") | Y30: =IF(J30=0,0,(J30+P30)*0.33+18) -> 37.47 | AA30: =IF(OR(S30="", T30="", U30=""), "", MAX(R30,S30)*40%+T30*30%+U30*30%) | AB30: =IF(AA30="", "", MAX(X30, Y30)-AA30) | AD30: =IFERROR(MIN((MAX(R30,S30)*70%+U30*30%), Y30), "") | AE30: =IF(AD30="", "", MAX(AA30, AB30)-AD30)
C31: 3 | D31: 8 | E31: ='CRU historical'!F8 | F31: ='CRU historical'!I8 -> 8 | G31: ='CRU historical'!L8 | H31: ='CRU historical'!O8 | I31: ='CRU historical'!R8 | J31: =AVERAGE('CRU historical'!U8, 'CRU historical'!X8, 'CRU historical'!AA8, 'CRU historical'!AD8) -> 38.5 | L31: {=IFERROR(SUMPRODUCT(('Sulphuric Acid freights'!$B$3:$B$513=B41)*('Sulphuric Acid freights'!$D$3:$D$513=D31)*('Sulphuric Acid freights'!$P$3:$P$513))/SUMPRODUCT(('Sulphuric Acid freights'!$B$3:$B$513=B41)*('Sulphuric Acid freights'!$D$3:$D$513=D31)*1), AVERAGE('Sulphuric Acid freights'!$P$3:$P$513))*2/3} -> 54.110672 | M31: {=IFERROR(SUMPRODUCT(('Sulphuric Acid freights'!$B$3:$B$513=B41)*('Sulphuric Acid freights'!$D$3:$D$513=D31)*('Sulphuric Acid freights'!$M$3:$M$513))/SUMPRODUCT(('Sulphuric Acid freights'!$B$3:$B$513=B41)*('Sulphuric Acid freights'!$D$3:$D$513=D31)*1)*2/3, AVERAGE('Sulphuric Acid freights'!$M$3:$M$513))} -> 23.573123 | N31: =IFERROR(L31*0.9, "") -> 48.699605 | O31: {=IF(SUMPRODUCT(('Sulphur freight'!$B$3:$B$1976=B41)*('Sulphur freight'!$D$3:$D$1976=D31)*('Sulphur freight'!$G$3:$G$1976))/SUMPRODUCT(('Sulphur freight'!$B$3:$B$1976=B41)*('Sulphur freight'!$D$3:$D$1976=D31)*1)=0, AVERAGE('Sulphur freight'!$G$3:$G$1976),SUMPRODUCT(('Sulphur freight'!$B$3:$B$1976=B41)*('Sulphur freight'!$D$3:$D$1976=D31)*('Sulphur freight'!$G$3:$G$1976))/SUMPRODUCT(('Sulphur freight'!$B$3:$B$1976=B41)*('Sulphur freight'!$D$3:$D$1976=D31)*1))} -> 29.165429 | P31: 20 | R31: =H31 | S31: =IF(F31=0, "", F31+M31) -> 31.573123 | T31: =IFERROR( E31+L31, "") | U31: =IFERROR( G31+N31, "") | V31: =IFERROR(I31+O31, "") | W31: =J31+P31 -> 58.5 | X31: =IFERROR((I31+O31)*0.33+18, "") | Y31: =IF(J31=0,0,(J31+P31)*0.33+18) -> 37.305 | AA31: =IF(OR(S31="", T31="", U31=""), "", MAX(R31,S31)*40%+T31*30%+U31*30%) | AB31: =IF(AA31="", "", MAX(X31, Y31)-AA31) | AD31: =IFERROR(MIN((MAX(R31,S31)*70%+U31*30%), Y31), "") | AE31: =IF(AD31="", "", MAX(AA31, AB31)-AD31)
C32: 3 | D32: 9 | E32: ='CRU historical'!F9 | F32: ='CRU historical'!I9 -> 8 | G32: ='CRU historical'!L9 | H32: ='CRU historical'!O9 | I32: ='CRU historical'!R9 | J32: =AVERAGE('CRU historical'!U9, 'CRU historical'!X9, 'CRU historical'!AA9, 'CRU historical'!AD9) -> 38 | L32: {=IFERROR(SUMPRODUCT(('Sulphuric Acid freights'!$B$3:$B$513=B42)*('Sulphuric Acid freights'!$D$3:$D$513=D32)*('Sulphuric Acid freights'!$P$3:$P$513))/SUMPRODUCT(('Sulphuric Acid freights'!$B$3:$B$513=B42)*('Sulphuric Acid freights'!$D$3:$D$513=D32)*1), AVERAGE('Sulphuric Acid freights'!$P$3:$P$513))*2/3} -> 54.110672 | M32: {=IFERROR(SUMPRODUCT(('Sulphuric Acid freights'!$B$3:$B$513=B42)*('Sulphuric Acid freights'!$D$3:$D$513=D32)*('Sulphuric Acid freights'!$M$3:$M$513))/SUMPRODUCT(('Sulphuric Acid freights'!$B$3:$B$513=B42)*('Sulphuric Acid freights'!$D$3:$D$513=D32)*1)*2/3, AVERAGE('Sulphuric Acid freights'!$M$3:$M$513))} -> 23.573123 | N32: =IFERROR(L32*0.9, "") -> 48.699605 | O32: {=IF(SUMPRODUCT(('Sulphur freight'!$B$3:$B$1976=B42)*('Sulphur freight'!$D$3:$D$1976=D32)*('Sulphur freight'!$G$3:$G$1976))/SUMPRODUCT(('Sulphur freight'!$B$3:$B$1976=B42)*('Sulphur freight'!$D$3:$D$1976=D32)*1)=0, AVERAGE('Sulphur freight'!$G$3:$G$1976),SUMPRODUCT(('Sulphur freight'!$B$3:$B$1976=B42)*('Sulphur freight'!$D$3:$D$1976=D32)*('Sulphur freight'!$G$3:$G$1976))/SUMPRODUCT(('Sulphur freight'!$B$3:$B$1976=B42)*('Sulphur freight'!$D$3:$D$1976=D32)*1))} -> 29.165429 | P32: 20 | R32: =H32 | S32: =IF(F32=0, "", F32+M32) -> 31.573123 | T32: =IFERROR( E32+L32, "") | U32: =IFERROR( G32+N32, "") | V32: =IFERROR(I32+O32, "") | W32: =J32+P32 -> 58 | X32: =IFERROR((I32+O32)*0.33+18, "") | Y32: =IF(J32=0,0,(J32+P32)*0.33+18) -> 37.14 | AA32: =IF(OR(S32="", T32="", U32=""), "", MAX(R32,S32)*40%+T32*30%+U32*30%) | AB32: =IF(AA32="", "", MAX(X32, Y32)-AA32) | AD32: =IFERROR(MIN((MAX(R32,S32)*70%+U32*30%), Y32), "") | AE32: =IF(AD32="", "", MAX(AA32, AB32)-AD32)
C33: 4 | D33: 10 | E33: ='CRU historical'!F10 | F33: ='CRU historical'!I10 -> 8 | G33: ='CRU historical'!L10 | H33: ='CRU historical'!O10 | I33: ='CRU historical'!R10 | J33: =AVERAGE('CRU historical'!U10, 'CRU historical'!X10, 'CRU historical'!AA10, 'CRU historical'!AD10) -> 38 | L33: {=IFERROR(SUMPRODUCT(('Sulphuric Acid freights'!$B$3:$B$513=B43)*('Sulphuric Acid freights'!$D$3:$D$513=D33)*('Sulphuric Acid freights'!$P$3:$P$513))/SUMPRODUCT(('Sulphuric Acid freights'!$B$3:$B$513=B43)*('Sulphuric Acid freights'!$D$3:$D$513=D33)*1), AVERAGE('Sulphuric Acid freights'!$P$3:$P$513))*2/3} -> 54.110672 | M33: {=IFERROR(SUMPRODUCT(('Sulphuric Acid freights'!$B$3:$B$513=B43)*('Sulphuric Acid freights'!$D$3:$D$513=D33)*('Sulphuric Acid freights'!$M$3:$M$513))/SUMPRODUCT(('Sulphuric Acid freights'!$B$3:$B$513=B43)*('Sulphuric Acid freights'!$D$3:$D$513=D33)*1)*2/3, AVERAGE('Sulphuric Acid freights'!$M$3:$M$513))} -> 23.573123 | N33: =IFERROR(L33*0.9, "") -> 48.699605 | O33: {=IF(SUMPRODUCT(('Sulphur freight'!$B$3:$B$1976=B43)*('Sulphur freight'!$D$3:$D$1976=D33)*('Sulphur freight'!$G$3:$G$1976))/SUMPRODUCT(('Sulphur freight'!$B$3:$B$1976=B43)*('Sulphur freight'!$D$3:$D$1976=D33)*1)=0, AVERAGE('Sulphur freight'!$G$3:$G$1976),SUMPRODUCT(('Sulphur freight'!$B$3:$B$1976=B43)*('Sulphur freight'!$D$3:$D$1976=D33)*('Sulphur freight'!$G$3:$G$1976))/SUMPRODUCT(('Sulphur freight'!$B$3:$B$1976=B43)*('Sulphur freight'!$D$3:$D$1976=D33)*1))} -> 29.165429 | P33: 20 | R33: =H33 | S33: =IF(F33=0, "", F33+M33) -> 31.573123 | T33: =IFERROR( E33+L33, "") | U33: =IFERROR( G33+N33, "") | V33: =IFERROR(I33+O33, "") | W33: =J33+P33 -> 58 | X33: =IFERROR((I33+O33)*0.33+18, "") | Y33: =IF(J33=0,0,(J33+P33)*0.33+18) -> 37.14 | AA33: =IF(OR(S33="", T33="", U33=""), "", MAX(R33,S33)*40%+T33*30%+U33*30%) | AB33: =IF(AA33="", "", MAX(X33, Y33)-AA33) | AD33: =IFERROR(MIN((MAX(R33,S33)*70%+U33*30%), Y33), "") | AE33: =IF(AD33="", "", MAX(AA33, AB33)-AD33)
